Workbook

Sheet ДУ
A1: Дата сверки: | B1: 45911
A2: 1) Активы
A4: ЦБ
A5: Наименование эмитента и вид ЦБ | B5: ISIN | C5: Количество ЦБ | D5: Номинальная стоимость, тенге | E5: Ставка | F5: Дата зачисления/приобретения | G5: Дата погашения | H5: Чистая покупная стоимость | I5: Расчетная цена на 11/09/2025 | J5: Расчетная грязная цена на 11/09/2025 | K5: Накопленный купон | L5: Суммарно-текущая рыночная стоимость | M5: Вес
A6: Министерство Финансов Республики Казахстан MOM048_0052 | B6: KZK200000687 | C6: 4810000 | D6: 1000 | E6: 10.67 | F6: 45491 | H6: 4.919975e+09 | I6: =VLOOKUP(B6,'KASE (цены)'!$C:$G,4,0) -> 98.0241 | J6: =VLOOKUP(B6,'KASE (цены)'!$C:$G,5,0) -> 99.506 | K6: =71281527.78+0.01 -> 71281528 | L6: =ROUND(D6*C6*I6/100+K6,2) -> 4.7862407e+09 | M6: =L6/$L$32 -> 0.1023674
A7: Министерство Финансов Республики Казахстан MUM084_0018 | B7: KZKD00001137 | C7: 3607500 | D7: 1000 | E7: 10.4 | F7: 45491 | H7: 3401920600 | I7: =VLOOKUP(B7,'KASE (цены)'!$C:$G,4,0) -> 86.3134 | J7: =VLOOKUP(B7,'KASE (цены)'!$C:$G,5,0) -> 90.6178 | K7: 1.5528283e+08 | L7: =ROUND(D7*C7*I7/100+K7,2) -> 3.2690387e+09 | M7: =L7/$L$32 -> 0.069917709
A8: Министерство Финансов Республики Казахстан MUM096_0012 | B8: KZKD00001160 | C8: 3607500 | D8: 1000 | E8: 10.55 | F8: 45491 | H8: 3.617866e+09 | I8: =VLOOKUP(B8,'KASE (цены)'!$C:$G,4,0) -> 82.3168 | J8: =VLOOKUP(B8,'KASE (цены)'!$C:$G,5,0) -> 83.5769 | K8: 45459510 | L8: =ROUND(D8*C8*I8/100+K8,2) -> 3.0150381e+09 | M8: =L8/$L$32 -> 0.064485181
A9: Министерство Финансов Республики Казахстан MUM108_0013 | B9: KZKD00001087 | C9: 3607500 | D9: 1000 | E9: 11 | F9: 45491 | H9: 3.4333119e+09 | I9: =VLOOKUP(B9,'KASE (цены)'!$C:$G,4,0) -> 84.3192 | J9: =VLOOKUP(B9,'KASE (цены)'!$C:$G,5,0) -> 89.2386 | K9: 1.7746896e+08 | L9: =ROUND(D9*C9*I9/100+K9,2) -> 3.2192841e+09 | M9: =L9/$L$32 -> 0.068853565
A10: Министерство Финансов Республики Казахстан MUM120_0017 | B10: KZKD00000899 | C10: 2000000 | D10: 1000 | E10: 9 | F10: 45491 | H10: 1886150000 | I10: =VLOOKUP(B10,'KASE (цены)'!$C:$G,4,0) -> 89.5796 | J10: =VLOOKUP(B10,'KASE (цены)'!$C:$G,5,0) -> 94.2046 | K10: 92500000 | L10: =ROUND(D10*C10*I10/100+K10,2) -> 1884092000 | M10: =L10/$L$32 -> 0.040296677
A11: Министерство Финансов Республики Казахстан MUM120_0019 | B11: KZKD00001129 | C11: 3607500 | D11: 1000 | E11: 10.3 | F11: 45491 | H11: 3.2529673e+09 | I11: =VLOOKUP(B11,'KASE (цены)'!$C:$G,4,0) -> 76.9941 | J11: =VLOOKUP(B11,'KASE (цены)'!$C:$G,5,0) -> 81.9724 | K11: 179593375 | L11: =ROUND(D11*C11*I11/100+K11,2) -> 2.9571555e+09 | M11: =L11/$L$32 -> 0.063247198
A12: Министерство Финансов Республики Казахстан MUM132_0007 | B12: KZKD00001152 | C12: 3607500 | D12: 1000 | E12: 10.65 | F12: 45533 | H12: 3.5097668e+09 | I12: =VLOOKUP(B12,'KASE (цены)'!$C:$G,4,0) -> 75.4475 | J12: =VLOOKUP(B12,'KASE (цены)'!$C:$G,5,0) -> 76.7788 | K12: 48024844 | L12: =ROUND(D12*C12*I12/100+K12,2) -> 2.7697934e+09 | M12: =L12/$L$32 -> 0.059239925
A13: Министерство Финансов Республики Казахстан MUM156_0005 | B13: KZKD00000758 | C13: 1000000 | D13: 1000 | E13: 7.47 | F13: 45491 | H13: 884755500 | I13: =VLOOKUP(B13,'KASE (цены)'!$C:$G,4,0) -> 85.7524 | J13: =VLOOKUP(B13,'KASE (цены)'!$C:$G,5,0) -> 87.4332 | K13: 16807500 | L13: =ROUND(D13*C13*I13/100+K13,2) -> 874331500 | M13: =L13/$L$32 -> 0.018700071
A14: Министерство Финансов Республики Казахстан MUM168_0003 | B14: KZKD00000949 | C14: 3607500 | D14: 1000 | E14: 8.45 | F14: 45491 | H14: 2.84962e+09 | I14: =VLOOKUP(B14,'KASE (цены)'!$C:$G,4,0) -> 67.5683 | J14: =VLOOKUP(B14,'KASE (цены)'!$C:$G,5,0) -> 70.9718 | K14: 1.2278026e+08 | L14: =ROUND(D14*C14*I14/100+K14,2) -> 2.5603067e+09 | M14: =L14/$L$32 -> 0.054759455
A15: Министерство Финансов Республики Казахстан MUM180_0006 | B15: KZKD00000535 | C15: 6012500 | D15: 1000 | E15: 5.49 | F15: 45491 | H15: 5.0975989e+09 | I15: =VLOOKUP(B15,'KASE (цены)'!$C:$G,4,0) -> 84.8781 | J15: =VLOOKUP(B15,'KASE (цены)'!$C:$G,5,0) -> 87.3791 | K15: 150372625 | L15: =ROUND(D15*C15*I15/100+K15,2) -> 5.2536684e+09 | M15: =L15/$L$32 -> 0.11236467
A16: Министерство Финансов Республики Казахстан MUM240_0002 | B16: KZKD00000741 | C16: 3607500 | D16: 1000 | E16: 8.07 | F16: 45491 | H16: 2.637317e+09 | I16: =VLOOKUP(B16,'KASE (цены)'!$C:$G,4,0) -> 61.1867 | J16: =VLOOKUP(B16,'KASE (цены)'!$C:$G,5,0) -> 63.8543 | K16: 96233069 | L16: =ROUND(D16*C16*I16/100+K16,2) -> 2.3035433e+09 | M16: =L16/$L$32 -> 0.049267837
A17: Министерство Финансов Республики Казахстан MUM240_0004 | B17: KZKD00000832 | C17: 3607500 | D17: 1000 | E17: 8.07 | F17: 45503 | H17: 2.6814517e+09 | I17: =VLOOKUP(B17,'KASE (цены)'!$C:$G,4,0) -> 59.7636 | J17: =VLOOKUP(B17,'KASE (цены)'!$C:$G,5,0) -> 64.7401 | K17: 1.7952724e+08 | L17: =ROUND(D17*C17*I17/100+K17,2) -> 2.3354991e+09 | M17: =L17/$L$32 -> 0.049951304
A18: Евразийский Банк Развития EABRb52 | B18: KZ2D00011863 | C18: 3000000 | D18: 1000 | E18: 14.3 | F18: 45538 | H18: 3000000000 | I18: =VLOOKUP(B18,'KASE (цены)'!$C:$G,4,0) -> 94.470271 | J18: =VLOOKUP(B18,'KASE (цены)'!$C:$G,5,0) -> 94.788071 | K18: 9533333.3 | L18: =ROUND(D18*C18*I18/100+K18,2) -> 2.8436415e+09 | M18: =L18/$L$32 -> 0.060819376
A19: АО "Национальный управляющий холдинг "Байтерек" BTRKb17 | B19: KZ2C00012698 | C19: =2000000-200000-50000 -> 1750000 | D19: 1000 | E19: 13.89 | F19: 45624 | H19: 2000000000 | I19: =VLOOKUP(B19,'KASE (цены)'!$C:$G,4,0) -> 98.107243 | J19: =VLOOKUP(B19,'KASE (цены)'!$C:$G,5,0) -> 102.08134 | K19: 69546458 | L19: =ROUND(D19*C19*I19/100+K19,2) -> 1.7864232e+09 | M19: =L19/$L$32 -> 0.038207751
A20: Министерство Финансов Республики Казахстан MUM180_0009 | B20: KZKD00000717 | C20: 1000000 | D20: 1000 | E20: 7.22 | F20: 45729 | H20: 7.9958667e+08 | I20: =VLOOKUP(B20,'KASE (цены)'!$C:$G,4,0) -> 76.5075 | J20: =VLOOKUP(B20,'KASE (цены)'!$C:$G,5,0) -> 81.9426 | K20: 54350556 | L20: =ROUND(D20*C20*I20/100+K20,2) -> 8.1942556e+08 | M20: =L20/$L$32 -> 0.017525751
A21: Министерство Финансов Республики Казахстан MUM180_0008 | B21: KZKD00000659 | C21: 1000000 | D21: 1000 | E21: 6.5 | F21: 45736 | H21: 8.4411911e+08 | I21: =VLOOKUP(B21,'KASE (цены)'!$C:$G,4,0) -> 81.9438 | J21: =VLOOKUP(B21,'KASE (цены)'!$C:$G,5,0) -> 87.6674 | K21: 57236111 | L21: =ROUND(D21*C21*I21/100+K21,2) -> 8.7667411e+08 | M21: =L21/$L$32 -> 0.018750174
A22: Министерство Финансов Республики Казахстан MUM156_0005 | B22: KZKD00000758 | C22: =500000 -> 500000 | D22: =1000 -> 1000 | E22: 7.47 | F22: 45747 | H22: 456810500 | I22: =VLOOKUP(B22,'KASE (цены)'!$C:$G,4,0) -> 85.7524 | J22: =VLOOKUP(B22,'KASE (цены)'!$C:$G,5,0) -> 87.4332 | K22: 8403750 | L22: =ROUND(D22*C22*I22/100+K22,2) -> 437165750 | M22: =L22/$L$32 -> 0.0093500354
A23: Министерство Финансов Республики Казахстан MOM060_0054 | B23: KZK200000737 | C23: =500000 -> 500000 | D23: =1000 -> 1000 | E23: 15.35 | F23: 45755 | H23: 5.2596022e+08 | I23: =VLOOKUP(B23,'KASE (цены)'!$C:$G,4,0) -> 97.5887 | J23: =VLOOKUP(B23,'KASE (цены)'!$C:$G,5,0) -> 102.4069 | K23: 24090972 | L23: =ROUND(D23*C23*I23/100+K23,2) -> 5.1203447e+08 | M23: =L23/$L$32 -> 0.010951316
A24: Министерство Финансов Республики Казахстан MUM180_0009 | B24: KZKD00000717 | C24: 1000000 | D24: =1000 -> 1000 | E24: 7.22 | F24: 45799 | H24: 812416000 | I24: =VLOOKUP(B24,'KASE (цены)'!$C:$G,4,0) -> 76.5075 | J24: =VLOOKUP(B24,'KASE (цены)'!$C:$G,5,0) -> 81.9426 | K24: 54350556 | L24: =ROUND(D24*C24*I24/100+K24,2) -> 8.1942556e+08 | M24: =L24/$L$32 -> 0.017525751
A25: Министерство Финансов Республики Казахстан MUM180_0009 | B25: KZKD00000717 | C25: 1000000 | D25: =1000 -> 1000 | E25: 7.22 | F25: 45806 | H25: 801 815 888,89 | I25: =VLOOKUP(B25,'KASE (цены)'!$C:$G,4,0) -> 76.5075 | J25: =VLOOKUP(B25,'KASE (цены)'!$C:$G,5,0) -> 81.9426 | K25: 54350556 | L25: =ROUND(D25*C25*I25/100+K25,2) -> 8.1942556e+08 | M25: =L25/$L$32 -> 0.017525751
A26: Министерство Финансов Республики Казахстан MUM192_0002 | B26: KZKD00000543 | C26: =500000 -> 500000 | D26: 1000 | E26: 5 | F26: 45813 | H26: 3.7997089e+08 | I26: =VLOOKUP(B26,'KASE (цены)'!$C:$G,4,0) -> 75.7508 | J26: =VLOOKUP(B26,'KASE (цены)'!$C:$G,5,0) -> 77.7369 | K26: 9930555.6 | L26: =ROUND(D26*C26*I26/100+K26,2) -> 3.8868456e+08 | M26: =L26/$L$32 -> 0.0083131269
A27: Министерство Финансов Республики Казахстан MUM096_0011 | B27: KZKD00001095 | C27: =500000 -> 500000 | D27: 1000 | E27: 10.47 | F27: 45827 | H27: 4.5628667e+08 | I27: =VLOOKUP(B27,'KASE (цены)'!$C:$G,4,0) -> 84.5479 | J27: =VLOOKUP(B27,'KASE (цены)'!$C:$G,5,0) -> 93.6801 | K27: 45660833 | L27: =ROUND(D27*C27*I27/100+K27,2) -> 4.6840033e+08 | M27: =L27/$L$32 -> 0.010018076
A28: Министерство Финансов Республики Казахстан MUM096_0011 | B28: KZKD00001095 | C28: =500000 -> 500000 | D28: 1000 | E28: 10.47 | F28: 45827 | H28: 4.5520867e+08 | I28: =VLOOKUP(B28,'KASE (цены)'!$C:$G,4,0) -> 84.5479 | J28: =VLOOKUP(B28,'KASE (цены)'!$C:$G,5,0) -> 93.6801 | K28: 45660833 | L28: =ROUND(D28*C28*I28/100+K28,2) -> 4.6840033e+08 | M28: =L28/$L$32 -> 0.010018076
A29: Министерство Финансов Республики Казахстан MUM096_0011 | B29: KZKD00001095 | C29: =500000 -> 500000 | D29: 1000 | E29: 10.47 | F29: 45838 | H29: 457385750 | I29: =VLOOKUP(B29,'KASE (цены)'!$C:$G,4,0) -> 84.5479 | J29: =VLOOKUP(B29,'KASE (цены)'!$C:$G,5,0) -> 93.6801 | K29: 45660833 | L29: =ROUND(D29*C29*I29/100+K29,2) -> 4.6840033e+08 | M29: =L29/$L$32 -> 0.010018076
A30: Министерство Финансов Республики Казахстан MUM180_0009 | B30: KZKD00000717 | C30: =500000 -> 500000 | D30: 1000 | E30: 7.22 | F30: 45841 | H30: 4.0074189e+08 | I30: =VLOOKUP(B30,'KASE (цены)'!$C:$G,4,0) -> 76.5075 | J30: =VLOOKUP(B30,'KASE (цены)'!$C:$G,5,0) -> 81.9426 | K30: 27175278 | L30: =ROUND(D30*C30*I30/100+K30,2) -> 4.0971278e+08 | M30: =L30/$L$32 -> 0.0087628753
A31: Министерство Финансов Республики Казахстан MUM180_0009 | B31: KZKD00000717 | C31: =500000 -> 500000 | D31: 1000 | E31: 7.22 | F31: 45841 | H31: 4.0023189e+08 | I31: =VLOOKUP(B31,'KASE (цены)'!$C:$G,4,0) -> 76.5075 | J31: =VLOOKUP(B31,'KASE (цены)'!$C:$G,5,0) -> 81.9426 | K31: 27175278 | L31: =ROUND(D31*C31*I31/100+K31,2) -> 4.0971278e+08 | M31: =L31/$L$32 -> 0.0087628753
B32: ИТОГО | C32: =SUM(C6:C31) -> 55432500 | H32: =SUM(H26:H31) -> 2.5498258e+09 | K32: =SUM(K6:K31) -> 1.8684576e+09 | L32: =SUM(L6:L31) -> 4.6755518e+10 | M32: =SUM(M6:M31) -> 1
A34: Остатки на инвест. Счетах
A35: KZT | B35: 3146420.1
A38: Обратное репо
A39: Наименование эмитента и вид ЦБ | B39: НИН (ISIN) | C39: Количество | D39: Валюта | E39: Дата открытия | F39: Дата закрытия | G39: Цена открытия | H39: Цена закрытия | I39: Сумма открытия операции, в тг | J39: Сумма закрытия операции, в тг | K39: Ставка доходности, % | L39: Сумма начисленного вознагрждения | M39: Суммарная текущая стоимость, в тг
A40: MUM096_0011 | B40: KZKD00001095 | C40: 1852980 | D40: KZT | E40: 45911 | F40: 45912 | G40: 936.801 | H40: 937.21165 | I40: 1.7358735e+09 | J40: 1.7366344e+09 | K40: 16 | M40: 1.7358735e+09
A41: MUM084_0018 | B41: KZKD00001137 | C41: 1909920 | D41: KZT | E41: 45911 | F41: 45912 | G41: 906.178 | H41: 906.57277 | I41: 1.7307275e+09 | J41: 1.7314815e+09 | K41: 15.901 | M41: 1.7307275e+09
A42: MUM084_0018 | B42: KZKD00001137 | C42: 20976 | D42: KZT | E42: 45911 | F42: 45912 | G42: 906.178 | H42: 906.57277 | I42: 19007990 | J42: 19016270 | K42: 15.901 | M42: 19007990
A43: ИТОГО | M43: =SUM(M40:M42) -> 3.485609e+09
A45: Прочие активы (дебиторская задолженность, деньги в пути)
...

Sheet Лист2
A1: MOM048_0052 | B1: =VLOOKUP(A1,$C$1:$D$22,2,0) -> 4.8203466e+09 | C1: MOM048_0052 | D1: 4.8203466e+09 | E1: 4.8203466e+09 | F1: =E1-B1 -> 0
A2: MUM084_0018 | B2: =VLOOKUP(A2,$C$1:$D$22,2,0) -> 3.2044721e+09 | C2: MOM060_0054 | D2: 4.9772828e+08 | E2: 3.2044721e+09 | F2: =E2-B2 -> 0
A3: MUM096_0012 | B3: =VLOOKUP(A3,$C$1:$D$22,2,0) -> 3403024495 | C3: MUM084_0018 | D3: 3.2044721e+09 | E3: 3403024495 | F3: =E3-B3 -> 0
A4: MUM108_0013 | B4: =VLOOKUP(A4,$C$1:$D$22,2,0) -> 3.2107973e+09 | C4: MUM096_0012 | D4: 3403024495 | E4: 3.2107973e+09 | F4: =E4-B4 -> 0
A5: MUM120_0017 | B5: =VLOOKUP(A5,$C$1:$D$22,2,0) -> 1815862000 | C5: MUM108_0013 | D5: 3.2107973e+09 | E5: 1815862000 | F5: =E5-B5 -> 0
A6: MUM120_0019 | B6: =VLOOKUP(A6,$C$1:$D$22,2,0) -> 3.0585115e+09 | C6: MUM120_0017 | D6: 1815862000 | E6: 3.0585115e+09 | F6: =E6-B6 -> 0
A7: MUM132_0007 | B7: =VLOOKUP(A7,$C$1:$D$22,2,0) -> 3312336755 | C7: MUM120_0019 | D7: 3.0585115e+09 | E7: 3312336755 | F7: =E7-B7 -> 0
A8: MUM156_0005 | B8: =VLOOKUP(A8,$C$1:$D$22,2,0) -> 920275000 | C8: MUM132_0007 | D8: 3312336755 | E8: 920275000 | F8: =E8-B8 -> 0
A9: MUM168_0003 | B9: =VLOOKUP(A9,$C$1:$D$22,2,0) -> 2710855875 | C9: MUM156_0005 | D9: 920275000 | E9: 2710855875 | F9: =E9-B9 -> 0
A10: MUM180_0006 | B10: =VLOOKUP(A10,$C$1:$D$22,2,0) -> 5.0690335e+09 | C10: MUM156_0005 | D10: 460137500 | E10: 5.0690335e+09 | F10: =E10-B10 -> 0
A11: MUM240_0002 | B11: =VLOOKUP(A11,$C$1:$D$22,2,0) -> 2519480405 | C11: MUM168_0003 | D11: 2710855875 | E11: 2519480405 | F11: =E11-B11 -> 0
A12: MUM240_0004 | B12: =VLOOKUP(A12,$C$1:$D$22,2,0) -> 2.5642825e+09 | C12: MUM180_0006 | D12: 5.0690335e+09 | E12: 2.5642825e+09 | F12: =E12-B12 -> 0
... A18: MUM180_0008 | B18: =VLOOKUP(A18,$C$1:$D$22,2,0) -> 8.5276156e+08 | C18: BTRKb14 | D18: 1.527699e+09 | E18: 8.5276156e+08 | F18: =E18-B18 -> 0
A19: MUM156_0005 | B19: =VLOOKUP(A19,$C$1:$D$22,2,1) -> 460137500 | C19: BTRKb17 | D19: 1.8255688e+09 | E19: 460137500 | F19: =E19-B19 -> 0
A20: MOM060_0054 | B20: =VLOOKUP(A20,$C$1:$D$22,2,0) -> 4.9772828e+08 | C20: EABRb52 | D20: 3.0746266e+09 | E20: 4.9772828e+08 | F20: =E20-B20 -> 0
A21: MUM180_0009 | B21: =VLOOKUP(A21,$C$1:$D$22,2,0) -> 813803000 | C21: KFUSb68 | D21: 3.8312899e+08 | E21: 813803000 | F21: =E21-B21 -> 0
B23: =SUM(B1:B22) -> 4.6858535e+10 | D23: =SUM(D1:D22) -> 4.6858535e+10

Sheet KASE (цены)
A1: Дата оценки | B1: =TODAY() -> 45912
B3: Торговый код | C3: ISIN | D3: Алгоритмы и параметры расчета ЦБ | E3: Краткое наименование эмитента | F3: Расчетная цена | G3: Расчетная грязная | H3: Доходность до погашения. % годовых | I3: Дней до погашения | J3: Единица измерения цены
B4: AIRA | C4: KZ1C00004050 | D4: акции | E4: АО "Эйр Астана" | F4: 750.86 | G4: – | H4: – | I4: – | J4: тенге
B5: AIRAd | C5: US0090632078 | D5: производные ценные бумаги | E5: АО "Эйр Астана" | F5: 5.7 | G5: – | H5: – | I5: – | J5: usd
B6: AKZM | C6: KZ1C00001288 | D6: акции | E6: АО "Актюбинский завод металлоконструкций" | F6: 6301.35 | G6: – | H6: – | I6: – | J6: тенге
B7: ALMSb1 | C7: KZ2C00012953 | D7: долговые ценные бумаги | E7: АО "АК Алтыналмас" | F7: 100.2277 | G7: 101.8944 | H7: 7.89 | I7: 825 ( 2) | J7: чистая цена в %
B8: BCCIbe | C8: KZPF00000553 | D8: ценные бумаги инвестиционных фондов | E8: АО "BCC Invest" - дочерняя организация АО "Банк ЦентрКредит" | F8: 1474.56 | G8: – | H8: – | I8: – | J8: тенге
B9: BCCIrb | C9: KZPF00000231 | D9: ценные бумаги инвестиционных фондов | E9: АО "BCC Invest" - дочерняя организация АО "Банк ЦентрКредит" | F9: 7.27 | G9: – | H9: – | I9: – | J9: тенге
B10: BIGDb5 | C10: KZ2D00012861 | D10: долговые ценные бумаги | E10: Частная компания BI Development Ltd. | F10: 99.8909 | G10: 105.4159 | H10: 19.5 | I10: 618 ( 2) | J10: чистая цена в %
B11: BRKZe18 | C11: XS3032932645 | D11: долговые ценные бумаги | E11: АО "Банк Развития Казахстана" | F11: 103.3283 | G11: 105.7346 | H11: 4.8 | I11: 1 646 ( 5) | J11: чистая цена в %
B12: BTRKe1 | C12: XS3067899610 | D12: долговые ценные бумаги | E12: АО "Национальный управляющий холдинг "Байтерек" | F12: 101.4373 | G12: 103.2994 | H12: 4.86 | I12: 957 ( 3) | J12: чистая цена в %
B13: CCBN | C13: KZ0007786572 | D13: акции | E13: АО "Банк ЦентрКредит" | F13: 5517.84 | G13: – | H13: – | I13: – | J13: тенге
B14: CCBNp | C14: KZ000A0H0930 | D14: акции | E14: АО "Банк ЦентрКредит" | F14: 11271.66 | G14: – | H14: – | I14: – | J14: тенге
B15: CSECfe | C15: KZPF00000025 | D15: ценные бумаги инвестиционных фондов | E15: АО "Сентрас Секьюритиз" | F15: 5931987.8 | G15: – | H15: – | I15: – | J15: тенге
B16: CSECtf | C16: KZPF00000280 | D16: ценные бумаги инвестиционных фондов | E16: АО "Сентрас Секьюритиз" | F16: 1747648.3 | G16: – | H16: – | I16: – | J16: тенге
B17: EABRb40 | C17: KZ2D00009628 | D17: ценные бумаги международных финансовых организаций | E17: Евразийский банк развития | F17: 99.8058 | G17: 102.5228 | H17: 6.1 | I17: 189 ( 1) | J17: чистая цена в %
B18: EABRb42 | C18: KZ2D00009222 | D18: ценные бумаги международных финансовых организаций | E18: Евразийский банк развития | F18: 100 | G18: 100.7568 | H18: 16.24 | I18: 897 ( 2) | J18: чистая цена в %
B19: EABRb53 | C19: KZ2D00013620 | D19: ценные бумаги международных финансовых организаций | E19: Евразийский банк развития | F19: 100 | G19: 108.0548 | H19: 17.48 | I19: 928 ( 3) | J19: чистая цена в %
B20: FFIN_or | C20: KZPF00000082 | D20: ценные бумаги инвестиционных фондов | E20: АО "Фридом Финанс" | F20: 166.55 | G20: – | H20: – | I20: – | J20: usd
B21: FFINgw | C21: KZPF00000090 | D21: ценные бумаги инвестиционных фондов | E21: АО "Фридом Финанс" | F21: 5496.9 | G21: – | H21: – | I21: – | J21: тенге
B22: HFINhl | C22: KZPF00000538 | D22: ценные бумаги инвестиционных фондов | E22: АО "Дочерняя организация Народного Банка Казахстана "Halyk Finance" | F22: 53275.53 | G22: – | H22: – | I22: – | J22: тенге
B23: HFINhp | C23: KZPF00000546 | D23: ценные бумаги инвестиционных фондов | E23: АО "Дочерняя организация Народного Банка Казахстана "Halyk Finance" | F23: 74283.28 | G23: – | H23: – | I23: – | J23: тенге
B24: HFINhs | C24: KZPF00000520 | D24: ценные бумаги инвестиционных фондов | E24: АО "Дочерняя организация Народного Банка Казахстана "Halyk Finance" | F24: 73343.41 | G24: – | H24: – | I24: – | J24: тенге
B25: HFINhv | C25: KZPF00000041 | D25: ценные бумаги инвестиционных фондов | E25: АО "Дочерняя организация Народного Банка Казахстана "Halyk Finance" | F25: 583632.34 | G25: – | H25: – | I25: – | J25: тенге
B26: HSBK | C26: KZ000A0LE0S4 | D26: акции | E26: АО "Народный Банк Казахстана" | F26: 368.72 | G26: – | H26: – | I26: – | J26: тенге
B27: HSBKd | C27: US46627J3023 | D27: производные ценные бумаги | E27: АО "Народный Банк Казахстана" | F27: 27 | G27: – | H27: – | I27: – | J27: usd
B28: IFDR | C28: KZ1C00000256 | D28: акции | E28: АО "Teniz Capital Investment Banking" | F28: 9490.15 | G28: – | H28: – | I28: – | J28: тенге
B29: KASAb1 | C29: KZ2C00013753 | D29: долговые ценные бумаги | E29: АО "Казахстанский электролизный завод" | F29: 99.9872 | G29: 101.8108 | H29: 6.5 | I29: 979 ( 3) | J29: чистая цена в %
B30: KCEL | C30: KZ1C00000876 | D30: акции | E30: АО "Кселл" | F30: 3376.63 | G30: – | H30: – | I30: – | J30: тенге
B31: KEGC | C31: KZ1C00000959 | D31: акции | E31: АО "KEGOC" | F31: 1443.1 | G31: – | H31: – | I31: – | J31: тенге
B32: KMGZ | C32: KZ1C00001122 | D32: акции | E32: АО "Национальная компания "КазМунайГаз" | F32: 19764.35 | G32: – | H32: – | I32: – | J32: тенге
B33: KMGZe12 | C33: XS1595714087 | D33: долговые ценные бумаги | E33: АО "Национальная компания "КазМунайГаз" | F33: 91.7928 | G33: 94.0609 | H33: 6.46 | I33: 7 778 ( 22) | J33: чистая цена в %
B34: KMGZe14 | C34: XS1807300105 | D34: долговые ценные бумаги | E34: АО "Национальная компания "КазМунайГаз" | F34: 102.1203 | G34: 104.1658 | H34: 4.86 | I34: 1 663 ( 5) | J34: чистая цена в %
B35: KMGZe15 | C35: XS1807299331 | D35: долговые ценные бумаги | E35: АО "Национальная компания "КазМунайГаз" | F35: 97.2161 | G35: 99.6421 | H35: 6.61 | I35: 8 323 ( 23) | J35: чистая цена в %
B36: KMGZe16 | C36: XS2242422397 | D36: долговые ценные бумаги | E36: АО "Национальная компания "КазМунайГаз" | F36: 89.4758 | G36: 90.905 | H36: 5.19 | I36: 2 733 ( 8) | J36: чистая цена в %
B37: KSPI | C37: KZ1C00001536 | D37: акции | E37: АО Kaspi.kz | F37: 48850.99 | G37: – | H37: – | I37: – | J37: тенге
B38: KSPId | C38: US48581R2058 | D38: производные ценные бумаги | E38: АО Kaspi.kz | F38: 90.4 | G38: – | H38: – | I38: – | J38: usd
B39: KZ_23_3504 | C39: XS2914770545 | D39: государственные ценные бумаги | E39: Министерство финансов Республики Казахстан | F39: 98.875 | G39: 100.8654 | H39: 4.86 | I39: 3 448 ( 10) | J39: чистая цена в %
B40: KZAP | C40: KZ1C00001619 | D40: акции | E40: АО "Национальная атомная компания "Казатомпром" | F40: 25997.9 | G40: – | H40: – | I40: – | J40: тенге
B41: KZTCb3 | C41: KZ2C00012961 | D41: долговые ценные бумаги | E41: АО "Jusan Mobile" | F41: 105.9074 | G41: 116.5407 | H41: 18.93 | I41: 906 ( 3) | J41: чистая цена в %
...

Sheet Лист1
A1: KZKD00000543 | B1: MUM192_0002
A2: KZ2C00012698 | B2: BTRKb17
A3: KZKD00000717 | B3: MUM180_0009
A4: KZKD00000717 | B4: MUM180_0009
A5: KZKD00000717 | B5: MUM180_0009
A6: KZKD00000717 | B6: MUM180_0009
A7: KZKD00000717 | B7: MUM180_0009
A8: KZKD00001137 | B8: MUM084_0018
A9: KZKD00001152 | B9: MUM132_0007
A10: KZKD00000535 | B10: MUM180_0006
A11: KZKD00001087 | B11: MUM108_0013
A12: KZKD00000949 | B12: MUM168_0003
... A27: KZK200000687 | B27: MOM048_0052

Sheet купон расч.
A1: Сверка | C1: аис
A2: MOM048_0052 | B2: =VLOOKUP(A2,$C$2:$D$28,2,0) -> 62727744 | C2: MUM192_0002 | D2: 9513888.9
A3: MUM084_0018 | B3: =VLOOKUP(A3,$C$2:$D$28,2,0) -> 1.4902983e+08 | C3: BTRKb17 | D3: 65495208
A4: MUM096_0012 | B4: =VLOOKUP(A4,$C$2:$D$28,2,0) -> 39116323 | C4: MUM180_0009 | D4: 26573611
A5: MUM108_0013 | B5: =VLOOKUP(A5,$C$2:$D$28,2,0) -> 1.7085521e+08 | C5: MUM180_0009 | D5: 26573611
A6: MUM120_0017 | B6: =VLOOKUP(A6,$C$2:$D$28,2,0) -> 89500000 | C6: MUM180_0009 | D6: 53147222
A7: MUM120_0019 | B7: =VLOOKUP(A7,$C$2:$D$28,2,0) -> 173400500 | C7: MUM180_0009 | D7: 53147222
A8: MUM132_0007 | B8: =VLOOKUP(A8,$C$2:$D$28,2,0) -> 41621531 | C8: MUM180_0009 | D8: 53147222
A9: MUM156_0005 | B9: =D22 -> 7781250 | C9: MUM084_0018 | D9: 1.4902983e+08
A10: MUM168_0003 | B10: =VLOOKUP(A10,$C$2:$D$28,2,0) -> 1.176997e+08 | C10: MUM132_0007 | D10: 41621531
A11: MUM180_0006 | B11: =VLOOKUP(A11,$C$2:$D$28,2,0) -> 1.4487119e+08 | C11: MUM180_0006 | D11: 1.4487119e+08
A12: MUM240_0002 | B12: =VLOOKUP(A12,$C$2:$D$28,2,0) -> 91380981 | C12: MUM108_0013 | D12: 1.7085521e+08
A13: MUM240_0004 | B13: =VLOOKUP(A13,$C$2:$D$28,2,0) -> 174675150 | C13: MUM168_0003 | D13: 1.176997e+08
A14: EABRb52 | B14: =VLOOKUP(A14,$C$2:$D$28,2,0) -> 2383333.3 | C14: MUM180_0008 | D14: 56152778
A15: BTRKb14 | B15: =VLOOKUP(A15,$C$2:$D$28,2,0) -> 1.0113542e+08 | C15: MUM120_0017 | D15: 89500000
A16: BTRKb17 | B16: =VLOOKUP(A16,$C$2:$D$28,2,0) -> 65495208 | C16: MUM120_0019 | D16: 173400500
A17: MUM180_0009 | B17: =D7 -> 53147222 | C17: MOM060_0054 | D17: 22811806
A18: MUM180_0008 | B18: =VLOOKUP(A18,$C$2:$D$28,2,0) -> 56152778 | C18: MUM096_0011 | D18: 44788333
A19: MUM156_0005 | B19: =D21 -> 15562500 | C19: MUM096_0011 | D19: 44788333
A20: MOM060_0054 | B20: =VLOOKUP(A20,$C$2:$D$28,2,0) -> 22811806 | C20: MUM096_0011 | D20: 44788333
A21: MUM180_0009 | B21: =D7 -> 53147222 | C21: MUM156_0005 | D21: 15562500
A22: MUM180_0009 | B22: =D8 -> 53147222 | C22: MUM156_0005 | D22: 7781250
A23: MUM192_0002 | B23: =VLOOKUP(A23,$C$2:$D$28,2,0) -> 9513888.9 | C23: EABRb52 | D23: 2383333.3
A24: MUM096_0011 | B24: =VLOOKUP(A24,$C$2:$D$28,2,0) -> 44788333 | C24: BTRKb14 | D24: 1.0113542e+08
A25: MUM096_0011 | B25: =VLOOKUP(A25,$C$2:$D$28,2,0) -> 44788333 | C25: MUM096_0012 | D25: 39116323
A26: MUM096_0011 | B26: =VLOOKUP(A26,$C$2:$D$28,2,0) -> 44788333 | C26: MUM240_0002 | D26: 91380981
A27: MUM180_0009 | B27: =D5 -> 26573611 | C27: MUM240_0004 | D27: 174675150
A28: MUM180_0009 | B28: =D5 -> 26573611 | C28: MOM048_0052 | D28: 62727744
B30: =SUM(B2:B28) -> 1.8826682e+09 | D30: =SUM(D2:D28) -> 1.8826682e+09
C31: =D30=B30 -> TRUE
C33: =B30-D30 -> 0
