Workbook

Sheet ДУ
A1: Сентрас Секьюритиз | B1: 45950
A2: 1) Активы
A4: ЦБ
A5: Наименование эмитента и вид ЦБ | B5: ISIN | C5: Количество ЦБ | D5: Номинальная стоимость. тенге | E5: Ставка | F5: Дата зачисления/приобретения | G5: Дата погашения | H5: Чистая покупная стоимоcть | I5: Расчетная цена на 20.10.25 | J5: Расчетная грязная цена 20.10.25 | K5: Накопленный купон | L5: Суммарно-текущая рыночная стоимость | M5: Вес
A6: Министерство Финансов Республики Казахстан купонные МЕУКАМ | B6: KZKD00000535 | C6: =3250000-500000-500000-500000 -> 1750000 | D6: =3250000000-500000000-500000000-500000000 -> 1750000000 | E6: 5.49 | F6: 45491 | G6: 27.03.2027 | H6: =2755458875/3250000000*D6 -> 1483708625 | I6: =VLOOKUP(B6,'KASE за 20.10.25'!$C$5:$F$162,4,0) -> 86.4866 | J6: =VLOOKUP(B6,'KASE за 20.10.25'!$C$5:$G$162,5,0) -> 89.5824 | K6: 54175625 | L6: =D6*I6/100+K6 -> 1567691125 | M6: =L6/$L$62 -> 0.058919906 | N6: =D6*E6%/360 -> 266875 | O6: =K6+N6 -> 54442500
A7: Министерство Финансов Республики Казахстан купонные МЕУКАМ | B7: KZKD00001137 | C7: 1950000 | D7: 1950000000 | E7: 10.4 | F7: 45491 | G7: 12.04.2028 | H7: 1838876000 | I7: =VLOOKUP(B7,'KASE за 20.10.25'!$C$5:$F$162,4,0) -> 87.5467 | J7: =VLOOKUP(B7,'KASE за 20.10.25'!$C$5:$G$162,5,0) -> 92.9778 | K7: 1.0590667e+08 | L7: =D7*I7/100+K7 -> 1.8130673e+09 | M7: =L7/$L$62 -> 0.068142094 | N7: =D7*E7%/360 -> 563333.33 | O7: =K7+N7 -> 1.0647e+08
A8: Министерство Финансов Республики Казахстан МЕУКАМ | B8: KZKD00001087 | C8: =1950000-202300-182000-187350 -> 1378350 | D8: =C8*1000 -> 1378350000 | E8: 11 | F8: 45491 | G8: 31.03.2029 | H8: =1855844250/1950000000*D8 -> 1.3117964e+09 | I8: =VLOOKUP(B8,'KASE за 20.10.25'!$C$5:$F$162,4,0) -> 85.2578 | J8: =VLOOKUP(B8,'KASE за 20.10.25'!$C$5:$G$162,5,0) -> 91.3689 | K8: 84232500 | L8: =D8*I8/100+K8 -> 1.2593834e+09 | M8: =L8/$L$62 -> 0.047332507 | N8: =D8*E8%/360 -> 421162.5 | O8: =K8+N8 -> 84653662
A9: Министерство Финансов Республики Казахстан купонные МЕУКАМ | B9: KZKD00001160 | C9: =1950000-225000-225000-208000-225000-225000 -> 842000 | D9: =C9*1000 -> 842000000 | E9: 10.55 | F9: 45491 | G9: 28.07.2029 | H9: =1504310166.66923/1500000000*D9 -> 8.4441944e+08 | I9: =VLOOKUP(B9,'KASE за 20.10.25'!$C$5:$F$162,4,0) -> 83.111 | J9: =VLOOKUP(B9,'KASE за 20.10.25'!$C$5:$G$162,5,0) -> 85.5141 | K9: 20233728 | L9: =D9*I9/100+K9 -> 7.2002835e+08 | M9: =L9/$L$62 -> 0.027061455 | N9: =D9*E9%/360 -> 246752.78 | O9: =K9+N9 -> 20480481
A10: Министерство Финансов Республики Казахстан купонные МЕУКАМ | B10: KZKD00001129 | C10: 1450000 | D10: 1450000000 | E10: 10.3 | F10: 45491 | G10: 17.03.2031 | H10: 1.307499e+09 | I10: =VLOOKUP(B10,'KASE за 20.10.25'!$C$5:$F$162,4,0) -> 77.3249 | J10: =VLOOKUP(B10,'KASE за 20.10.25'!$C$5:$G$162,5,0) -> 83.4191 | K10: 88365417 | L10: =D10*I10/100+K10 -> 1.2095765e+09 | M10: =L10/$L$62 -> 0.04546057 | N10: =D10*E10%/360 -> 414861.11 | O10: =K10+N10 -> 88780278
A11: Министерство Финансов Республики Казахстан МЕУКАМ | B11: KZKD00000949 | C11: 1950000 | D11: 1950000000 | E11: 8.45 | F11: 45491 | G11: 16.04.2032 | H11: 1.5403351e+09 | I11: =VLOOKUP(B11,'KASE за 20.10.25'!$C$5:$F$162,4,0) -> 67.6377 | J11: =VLOOKUP(B11,'KASE за 20.10.25'!$C$5:$G$162,5,0) -> 71.9566 | K11: 84218333 | L11: =D11*I11/100+K11 -> 1.4031535e+09 | M11: =L11/$L$62 -> 0.052735944 | N11: =D11*E11%/360 -> 457708.33 | O11: =K11+N11 -> 84676042
A12: Министерство Финансов Республики Казахстан Купонные Облигации | B12: KZKD00001152 | C12: =1950000-250000-250000-250000-218000 -> 982000 | D12: =C12*1000 -> 982000000 | E12: 10.65 | F12: 45491 | G12: 26.07.2032 | H12: =1897171250/1950000000*D12 -> 9.5539598e+08 | I12: =VLOOKUP(B12,'KASE за 20.10.25'!$C$5:$F$162,4,0) -> 75.3574 | J12: =VLOOKUP(B12,'KASE за 20.10.25'!$C$5:$G$162,5,0) -> 77.8424 | K12: 24402700 | L12: =D12*I12/100+K12 -> 764412368 | M12: =L12/$L$62 -> 0.028729578 | N12: =D12*E12%/360 -> 290508.33 | O12: =K12+N12 -> 24693208
A13: Министерство Финансов Республики Казахстан Купонные Облигации | B13: KZKD00001152 | C13: 250000 | D13: =C13*1000 -> 250000000 | E13: 10.65 | F13: 45673 | G13: 26.07.2032 | H13: =227969916.67/250000000*D13 -> 2.2796992e+08 | I13: =VLOOKUP(B13,'KASE за 20.10.25'!$C$5:$F$162,4,0) -> 75.3574 | J13: =VLOOKUP(B13,'KASE за 20.10.25'!$C$5:$G$162,5,0) -> 77.8424 | K13: 6212500 | L13: =D13*I13/100+K13 -> 194606000 | M13: =L13/$L$62 -> 0.0073140474 | N13: =D13*E13%/360 -> 73958.333 | O13: =K13+N13 -> 6286458.3
A14: Министерство Финансов Республики Казахстан купонные МЕУКАМ | B14: KZKD00000741 | C14: 1950000 | D14: 1950000000 | E14: 8.07 | F14: 45491 | G14: 12.05.2034 | H14: 1425576750 | I14: =VLOOKUP(B14,'KASE за 20.10.25'!$C$5:$F$177,4,0) -> 60.8497 | J14: =VLOOKUP(B14,'KASE за 20.10.25'!$C$5:$G$177,5,0) -> 64.3915 | K14: 69065750 | L14: =D14*I14/100+K14 -> 1255634900 | M14: =L14/$L$62 -> 0.047191624 | N14: =D14*E14%/360 -> 437125 | O14: =K14+N14 -> 69502875
A15: Министерство Финансов Республики Казахстан купонные МЕУКАМ | B15: KZKD00000832 | C15: 1950000 | D15: 1950000000 | E15: 8.07 | F15: 45491 | G15: 29.01.2035 | H15: 1449433375 | I15: =VLOOKUP(B15,'KASE за 20.10.25'!$C$5:$F$177,4,0) -> 59.3602 | J15: =VLOOKUP(B15,'KASE за 20.10.25'!$C$5:$G$177,5,0) -> 65.211 | K15: 114089625 | L15: =D15*I15/100+K15 -> 1271613525 | M15: =L15/$L$62 -> 0.047792163 | N15: =D15*E15%/360 -> 437125 | O15: =K15+N15 -> 114526750
A16: Министерство Финансов Республики Казахстан купонные МЕУКАМ | B16: KZKD00000550 | C16: =312000-1 -> 311999 | D16: =C16*1000 -> 311999000 | E16: 5.5 | F16: 45509 | G16: 48328 | H16: 2.0448962e+08 | I16: =VLOOKUP(B16,'KASE за 20.10.25'!$C$5:$F$177,4,0) -> 56.5072 | J16: =VLOOKUP(B16,'KASE за 20.10.25'!$C$5:$G$177,5,0) -> 59.1961 | K16: 8389306.4 | L16: =D16*I16/100+K16 -> 1.8469121e+08 | M16: =L16/$L$62 -> 0.006941411 | N16: =D16*E16%/360 -> 47666.514 | O16: =K16+N16 -> 8436973
A17: Министерство Финансов Республики Казахстан купонные МЕУКАМ | B17: KZKD00000550 | C17: 500000 | D17: 500000000 | E17: 5.5 | F17: 45532 | G17: 48328 | H17: 3.2653072e+08 | I17: =VLOOKUP(B17,'KASE за 20.10.25'!$C$5:$F$177,4,0) -> 56.5072 | J17: =VLOOKUP(B17,'KASE за 20.10.25'!$C$5:$G$177,5,0) -> 59.1961 | K17: 13444444 | L17: =D17*I17/100+K17 -> 2.9598044e+08 | M17: =L17/$L$62 -> 0.011124092 | N17: =D17*E17%/360 -> 76388.889 | O17: =K17+N17 -> 13520833
A18: Министерство Финансов Республики Казахстан купонные МЕУКАМ | B18: KZKD00000550 | C18: 500000 | D18: 500000000 | E18: 5.5 | F18: 45566 | G18: 48328 | H18: 3.3409056e+08 | I18: =VLOOKUP(B18,'KASE за 20.10.25'!$C$5:$F$177,4,0) -> 56.5072 | J18: =VLOOKUP(B18,'KASE за 20.10.25'!$C$5:$G$177,5,0) -> 59.1961 | K18: 13444444 | L18: =D18*I18/100+K18 -> 2.9598044e+08 | M18: =L18/$L$62 -> 0.011124092 | N18: =D18*E18%/360 -> 76388.889 | O18: =K18+N18 -> 13520833
A19: Министерство Финансов Республики Казахстан купонные МЕУКАМ | B19: KZKD00000550 | C19: 300000 | D19: =C19*1000 -> 300000000 | E19: 5.5 | F19: 45649 | G19: 48328 | H19: 2.0566557e+08 | I19: =VLOOKUP(B19,'KASE за 20.10.25'!$C$5:$F$177,4,0) -> 56.5072 | J19: =VLOOKUP(B19,'KASE за 20.10.25'!$C$5:$G$177,5,0) -> 59.1961 | K19: 8066666.7 | L19: =D19*I19/100+K19 -> 1.7758827e+08 | M19: =L19/$L$62 -> 0.006674455 | N19: =D19*E19%/360 -> 45833.333 | O19: =K19+N19 -> 8112500
A20: Министерство Финансов Республики Казахстан купонные МЕУКАМ | B20: KZKD00000550 | C20: 300000 | D20: =C20*1000 -> 300000000 | E20: 5.5 | F20: 45677 | G20: 48328 | H20: 2.0236587e+08 | I20: =VLOOKUP(B20,'KASE за 20.10.25'!$C$5:$F$177,4,0) -> 56.5072 | J20: =VLOOKUP(B20,'KASE за 20.10.25'!$C$5:$G$177,5,0) -> 59.1961 | K20: 8066666.7 | L20: =D20*I20/100+K20 -> 1.7758827e+08 | M20: =L20/$L$62 -> 0.006674455 | N20: =D20*E20%/360 -> 45833.333 | O20: =K20+N20 -> 8112500
A21: Министерство Финансов Республики Казахстан купонные МЕУКАМ | B21: KZKD00001160 | C21: 500000 | D21: =C21*1000 -> 500000000 | E21: 10.55 | F21: 45512 | G21: 28.07.2029 | H21: 4.5194078e+08 | I21: =VLOOKUP(B21,'KASE за 20.10.25'!$C$5:$F$162,4,0) -> 83.111 | J21: =VLOOKUP(B21,'KASE за 20.10.25'!$C$5:$G$162,5,0) -> 85.5141 | K21: 12015278 | L21: =D21*I21/100+K21 -> 4.2757028e+08 | M21: =L21/$L$62 -> 0.016069747 | N21: =D21*E21%/360 -> 146527.78 | O21: =K21+N21 -> 12161806
A22: Министерство Финансов Республики Казахстан купонные МЕУКАМ | B22: KZKD00001160 | C22: 553430 | D22: =C22*1000 -> 553430000 | E22: 10.55 | F22: 45512 | G22: 28.07.2029 | H22: 4.9999941e+08 | I22: =VLOOKUP(B22,'KASE за 20.10.25'!$C$5:$F$162,4,0) -> 83.111 | J22: =VLOOKUP(B22,'KASE за 20.10.25'!$C$5:$G$162,5,0) -> 85.5141 | K22: 13299230 | L22: =D22*I22/100+K22 -> 4.7326044e+08 | M22: =L22/$L$62 -> 0.017786961 | N22: =D22*E22%/360 -> 162185.74 | O22: =K22+N22 -> 13461416
A23: Министерство Финансов Республики Казахстан МЕУКАМ | B23: KZKD00000543 | C23: 636055 | D23: =C23*1000 -> 636055000 | E23: 5 | F23: 45519 | G23: 46861 | H23: 4.9999966e+08 | I23: =VLOOKUP(B23,'KASE за 20.10.25'!$C$5:$F$170,4,0) -> 77.2659 | J23: =VLOOKUP(B23,'KASE за 20.10.25'!$C$5:$G$170,5,0) -> 79.7937 | K23: 16078057 | L23: =D23*I23/100+K23 -> 5.0753168e+08 | M23: =L23/$L$62 -> 0.019075007 | N23: =D23*E23%/360 -> 88340.972 | O23: =K23+N23 -> 16166398
A24: Министерство Финансов Республики Казахстан купонные МЕУКАМ | B24: KZKD00000774 | C24: =715927-16841 -> 699086 | D24: =C24*1000 -> 699086000 | E24: 8.35 | F24: 45526 | G24: 50976 | H24: 4.8823782e+08 | I24: =VLOOKUP(B24,'KASE за 20.10.25'!$C$5:$F$177,4,0) -> 54.5796 | J24: =VLOOKUP(B24,'KASE за 20.10.25'!$C$5:$G$177,5,0) -> 56.5511 | K24: 13782675 | L24: =D24*I24/100+K24 -> 3.9534102e+08 | M24: =L24/$L$62 -> 0.014858447 | N24: =D24*E24%/360 -> 162149.11 | O24: =K24+N24 -> 13944824
A25: Министерство Финансов Республики Казахстан купонные МЕУКАМ | B25: KZKD00000774 | C25: 284073 | D25: =C25*1000 -> 284073000 | E25: 8.35 | F25: 45617 | G25: 50976 | H25: 2.0393645e+08 | I25: =VLOOKUP(B25,'KASE за 20.10.25'!$C$5:$F$177,4,0) -> 54.5796 | J25: =VLOOKUP(B25,'KASE за 20.10.25'!$C$5:$G$177,5,0) -> 56.5511 | K25: 5600578.1 | L25: =D25*I25/100+K25 -> 1.6064649e+08 | M25: =L25/$L$62 -> 0.0060377173 | N25: =D25*E25%/360 -> 65889.154 | O25: =K25+N25 -> 5666467.3
A26: Министерство Финансов Республики Казахстан МЕУКАМ | B26: KZKD00000840 | C26: 500000 | D26: =C26*1000 -> 500000000 | E26: 7.68 | F26: 45526 | G26: 47518 | H26: 417099000 | I26: =VLOOKUP(B26,'KASE за 20.10.25'!$C$5:$F$177,4,0) -> 73.0753 | J26: =VLOOKUP(B26,'KASE за 20.10.25'!$C$5:$G$177,5,0) -> 78.5366 | K26: 27306667 | L26: =D26*I26/100+K26 -> 3.9268317e+08 | M26: =L26/$L$62 -> 0.014758555 | N26: =D26*E26%/360 -> 106666.67 | O26: =K26+N26 -> 27413333
A27: Министерство Финансов Республики Казахстан МЕУКАМ | B27: KZKD00000840 | C27: 500000 | D27: =C27*1000 -> 500000000 | E27: 7.68 | F27: 45527 | G27: 47518 | H27: 4.1494417e+08 | I27: =VLOOKUP(B27,'KASE за 20.10.25'!$C$5:$F$177,4,0) -> 73.0753 | J27: =VLOOKUP(B27,'KASE за 20.10.25'!$C$5:$G$177,5,0) -> 78.5366 | K27: 27306667 | L27: =D27*I27/100+K27 -> 3.9268317e+08 | M27: =L27/$L$62 -> 0.014758555 | N27: =D27*E27%/360 -> 106666.67 | O27: =K27+N27 -> 27413333
A28: Министерство Финансов Республики Казахстан МЕУКАМ | B28: KZKD00000840 | C28: 500000 | D28: =C28*1000 -> 500000000 | E28: 7.68 | F28: 45561 | G28: 47518 | H28: 4.2179517e+08 | I28: =VLOOKUP(B28,'KASE за 20.10.25'!$C$5:$F$177,4,0) -> 73.0753 | J28: =VLOOKUP(B28,'KASE за 20.10.25'!$C$5:$G$177,5,0) -> 78.5366 | K28: 27306667 | L28: =D28*I28/100+K28 -> 3.9268317e+08 | M28: =L28/$L$62 -> 0.014758555 | N28: =D28*E28%/360 -> 106666.67 | O28: =K28+N28 -> 27413333
A29: Евразийский банк развития | B29: KZ2D00011863 | C29: 1700000 | D29: =C29*1000 -> 1700000000 | E29: 14.3 | F29: 45538 | G29: 46633 | H29: 1700000000 | I29: =VLOOKUP(B29,'Риск цены за 20.10.25'!$C$4:$G$963,4,0) -> 95.038429 | J29: =VLOOKUP(B29,'Риск цены за 20.10.25'!$C$4:$G$963,5,0) -> 96.905329 | K29: 31738056 | L29: =D29*I29/100+K29 -> 1.6473913e+09 | M29: =L29/$L$62 -> 0.061915349 | N29: =D29*E29%/360 -> 675277.78 | O29: =K29+N29 -> 32413333
A30: Министерство Финансов Республики Казахстан МЕУКАМ | B30: KZKD00001244 | C30: 500000 | D30: =C30*1000 -> 500000000 | E30: 12 | F30: 45540 | G30: 47901 | H30: 5.0216167e+08 | I30: =VLOOKUP(B30,'KASE за 20.10.25'!$C$5:$F$162,4,0) -> 83.0989 | J30: =VLOOKUP(B30,'KASE за 20.10.25'!$C$5:$G$162,5,0) -> 91.0322 | K30: 39666667 | L30: =D30*I30/100+K30 -> 4.5516117e+08 | M30: =L30/$L$62 -> 0.01710672 | N30: =D30*E30%/360 -> 166666.67 | O30: =K30+N30 -> 39833333
A31: Министерство Финансов Республики Казахстан МЕУКАМ | B31: KZKD00001251 | C31: 300000 | D31: =C31*1000 -> 300000000 | E31: 12 | F31: 45547 | G31: 47549 | H31: 302854400 | I31: =VLOOKUP(B31,'KASE за 20.10.25'!$C$5:$F$162,4,0) -> 85.3215 | J31: =VLOOKUP(B31,'KASE за 20.10.25'!$C$5:$G$162,5,0) -> 92.7548 | K31: 22300000 | L31: =D31*I31/100+K31 -> 278264500 | M31: =L31/$L$62 -> 0.010458258 | N31: =D31*E31%/360 -> 100000 | O31: =K31+N31 -> 22400000
A32: Министерство Финансов Республики Казахстан МЕУКАМ | B32: KZKD00001251 | C32: 288579 | D32: =C32*1000 -> 288579000 | E32: 12 | F32: 45582 | G32: 47549 | H32: 2.9999932e+08 | I32: =VLOOKUP(B32,'KASE за 20.10.25'!$C$5:$F$162,4,0) -> 85.3215 | J32: =VLOOKUP(B32,'KASE за 20.10.25'!$C$5:$G$162,5,0) -> 92.7548 | K32: 21451039 | L32: =D32*I32/100+K32 -> 2.6767097e+08 | M32: =L32/$L$62 -> 0.010060112 | N32: =D32*E32%/360 -> 96193 | O32: =K32+N32 -> 21547232
A33: АО "Национальный управляющий холдинг "Байтерек" | B33: KZ2C00012698 | C33: 300000 | D33: =C33*1000 -> 300000000 | E33: 13.89 | F33: 45624 | G33: 46109 | H33: 300000000 | I33: =VLOOKUP(B33,'Риск цены за 20.10.25'!$C$4:$G$963,4,0) -> 98.51584 | J33: =VLOOKUP(B33,'Риск цены за 20.10.25'!$C$4:$G$963,5,0) -> 103.99464 | K33: 16436500 | L33: =D33*I33/100+K33 -> 3.1198402e+08 | M33: =L33/$L$62 -> 0.011725568 | N33: =D33*E33%/360 -> 115750 | O33: =K33+N33 -> 16552250
A34: Министерство Финансов Республики Казахстан МЕУКАМ | B34: KZKD00000964 | C34: =220000-213000 -> 7000 | D34: =C34*1000 -> 7000000 | E34: 8.44 | F34: 45639 | G34: 47978 | H34: =182967986.67/220000000*D34 -> 5821708.7 | I34: =VLOOKUP(B34,'KASE за 20.10.25'!$C$5:$F$162,4,0) -> 70.57 | J34: =VLOOKUP(B34,'KASE за 20.10.25'!$C$5:$G$162,5,0) -> 74.3211 | K34: 262577.78 | L34: =D34*I34/100+K34 -> 5202477.8 | M34: =L34/$L$62 -> 0.00019552927 | N34: =D34*E34%/360 -> 1641.1111 | O34: =K34+N34 -> 264218.89
A35: Министерство Финансов Республики Казахстан МЕУКАМ | B35: KZKD00001236 | C35: =173000-163000 -> 10000 | D35: =C35*1000 -> 10000000 | E35: 14 | F35: 45639 | G35: 48353 | H35: =188266096.67/173000000*D35 -> 10882433 | I35: =VLOOKUP(B35,'KASE за 20.10.25'!$C$5:$F$162,4,0) -> 88.351 | J35: =VLOOKUP(B35,'KASE за 20.10.25'!$C$5:$G$162,5,0) -> 94.2232 | K35: 587222.22 | L35: =D35*I35/100+K35 -> 9422322.2 | M35: =L35/$L$62 -> 0.00035412737 | N35: =D35*E35%/360 -> 3888.8889 | O35: =K35+N35 -> 591111.11
A36: Министерство Финансов Республики Казахстан МЕУКАМ | B36: KZKD00001079 | C36: 300000 | D36: =C36*1000 -> 300000000 | E36: 8.7 | F36: 45651 | G36: 50082 | H36: 237511300 | I36: =VLOOKUP(B36,'KASE за 20.10.25'!$C$5:$F$177,4,0) -> 58.9865 | J36: =VLOOKUP(B36,'KASE за 20.10.25'!$C$5:$G$177,5,0) -> 65.004 | K36: 18052500 | L36: =D36*I36/100+K36 -> 195012000 | M36: =L36/$L$62 -> 0.0073293064 | N36: =D36*E36%/360 -> 72500 | O36: =K36+N36 -> 18125000
A37: Министерство Финансов Республики Казахстан МЕУКАМ | B37: KZKD00001079 | C37: 200000 | D37: =C37*1000 -> 200000000 | E37: 8.7 | F37: 45680 | G37: 50082 | H37: 157353400 | I37: =VLOOKUP(B37,'KASE за 20.10.25'!$C$5:$F$177,4,0) -> 58.9865 | J37: =VLOOKUP(B37,'KASE за 20.10.25'!$C$5:$G$177,5,0) -> 65.004 | K37: 12035000 | L37: =D37*I37/100+K37 -> 1.30008e+08 | M37: =L37/$L$62 -> 0.0048862043 | N37: =D37*E37%/360 -> 48333.333 | O37: =K37+N37 -> 12083333
A38: Министерство Финансов Республики Казахстан МЕУКАМ | B38: KZKD00001202 | C38: 263000 | D38: =C38*1000 -> 263000000 | E38: 11 | F38: 45656 | G38: 47518 | H38: 2.6372196e+08 | I38: =VLOOKUP(B38,'KASE за 20.10.25'!$C$5:$F$162,4,0) -> 82.6048 | J38: =VLOOKUP(B38,'KASE за 20.10.25'!$C$5:$G$162,5,0) -> 90.427 | K38: 20572444 | L38: =D38*I38/100+K38 -> 2.3782307e+08 | M38: =L38/$L$62 -> 0.0089383122 | N38: =D38*E38%/360 -> 80361.111 | O38: =K38+N38 -> 20652806
A39: Министерство Финансов Республики Казахстан МЕУКАМ | B39: KZKD00001210 | C39: 341000 | D39: =C39*1000 -> 341000000 | E39: 15.3 | F39: 45657 | G39: 47180 | H39: 396883762 | I39: =VLOOKUP(B39,'KASE за 20.10.25'!$C$5:$F$162,4,0) -> 95.8839 | J39: =VLOOKUP(B39,'KASE за 20.10.25'!$C$5:$G$162,5,0) -> 105.5314 | K39: 32897975 | L39: =D39*I39/100+K39 -> 359862074 | M39: =L39/$L$62 -> 0.013525011 | N39: =D39*E39%/360 -> 144925 | O39: =K39+N39 -> 33042900
A40: Министерство Финансов Республики Казахстан МЕУКАМ | B40: KZKD00001095 | C40: =214727-132000 -> 82727 | D40: =C40*1000 -> 82727000 | E40: 10.47 | F40: 45673 | G40: 47053 | H40: 77053072 | I40: =VLOOKUP(B40,'KASE за 20.10.25'!$C$5:$F$162,4,0) -> 85.7168 | J40: =VLOOKUP(B40,'KASE за 20.10.25'!$C$5:$G$162,5,0) -> 95.9832 | K40: 8493098.5 | L40: =D40*I40/100+K40 -> 79404036 | M40: =L40/$L$62 -> 0.0029843113 | N40: =D40*E40%/360 -> 24059.769 | O40: =K40+N40 -> 8517158.3
A41: Министерство Финансов Республики Казахстан МЕУКАМ | B41: KZKD00000790 | C41: 227500 | D41: =C41*1000 -> 227500000 | E41: 7.68 | F41: 45702 | G41: 47343 | H41: 1.8902823e+08 | I41: =VLOOKUP(B41,'KASE за 20.10.25'!$C$5:$F$177,4,0) -> 75.3711 | J41: =VLOOKUP(B41,'KASE за 20.10.25'!$C$5:$G$177,5,0) -> 76.8004 | K41: 3251733.3 | L41: =D41*I41/100+K41 -> 1.7472099e+08 | M41: =L41/$L$62 -> 0.0065666915 | N41: =D41*E41%/360 -> 48533.333 | O41: =K41+N41 -> 3300266.7
...

Sheet KASE за 20.10.25
A1: Дата оценки | B1: 45950
A3: № п/п | B3: Код | C3: ISIN | D3: Вид ценной бумаги | E3: Компания | F3: Рыночная цена | G3: Рыночная "грязная" цена | H3: Доходность до погашения, % годовых | I3: Срок до погашения | J3: Единица измерения цены
A5: 1 | B5: 1AIRA | C5: KZ1C00004050 | D5: акции | E5: Эйр Астана | F5: 814.74 | G5: – | H5: – | I5: – | J5: KZT
A6: 2 | B6: 2AKZM | C6: KZ1C00001288 | D6: акции | E6: Актюбинский завод металлоконструкций | F6: 6301.35 | G6: – | H6: – | I6: – | J6: KZT
A7: 3 | B7: 3ALMSb1 | C7: KZ2C00012953 | D7: долговые ЦБ | E7: АК Алтыналмас | F7: 100.0196 | G7: 100.5529 | H7: 7,99 | I7: 786 (2) | J7: %
A8: 4 | B8: 4BCCI_cc | C8: KZPF00000058 | D8: ЦБ инвест. фондов | E8: BCC Invest | F8: 129.95 | G8: – | H8: – | I8: – | J8: USD
A9: 5 | B9: 5BCCIbe | C9: KZPF00000553 | D9: ЦБ инвест. фондов | E9: BCC Invest | F9: 1498.51 | G9: – | H9: – | I9: – | J9: KZT
A10: 6 | B10: 6BCCIrb | C10: KZPF00000231 | D10: ЦБ инвест. фондов | E10: BCC Invest | F10: 7.18 | G10: – | H10: – | I10: – | J10: KZT
A11: 7 | B11: 7BCCIwah | C11: KZPF00000900 | D11: ЦБ инвест. фондов | E11: BCC Invest | F11: 100.98 | G11: – | H11: – | I11: – | J11: USD
A12: 8 | B12: 8BIGDb1 | C12: KZ2D00012457 | D12: долговые ЦБ | E12: Частная компания BI Development Ltd. | F12: 98.4052 | G12: 106.551 | H12: 19,01 | I12: 371 (1) | J12: %
A13: 9 | B13: 9BIGDb2 | C13: KZ2D00012531 | D13: долговые ЦБ | E13: Частная компания BI Development Ltd. | F13: 101.9879 | G13: 105.5296 | H13: 5,48 | I13: 371 (1) | J13: %
A14: 10 | B14: 10BIGDb5 | C14: KZ2D00012861 | D14: долговые ЦБ | E14: Частная компания BI Development Ltd. | F14: 100.6023 | G14: 108.2398 | H14: 18,99 | I14: 579 (2) | J14: %
A15: 11 | B15: 11BIGDb6 | C15: KZ2D00015328 | D15: долговые ЦБ | E15: Частная компания BI Development Ltd. | F15: 100.3368 | G15: 102.159 | H15: 20,23 | I15: 688 (2) | J15: %
A16: 12 | B16: 12BRKZe12 | C16: XS2337670694 | D16: долговые ЦБ | E16: Банк Развития Казахстана | F16: 86.9762 | G16: 88.3201 | H16: 5,72 | I16: 1 996 (6) | J16: %
A17: 13 | B17: 13BRKZe16 | C17: XS2917067204 | D17: долговые ЦБ | E17: Банк Развития Казахстана | F17: 100.185 | G17: 102.7662 | H17: 5,20 | I17: 1 443 (4) | J17: %
A18: 14 | B18: 14BRKZe18 | C18: XS3032932645 | D18: долговые ЦБ | E18: Банк Развития Казахстана | F18: 103.7841 | G18: 103.9872 | H18: 4,68 | I18: 1 607 (4) | J18: %
A19: 15 | B19: 15BRKZe21 | C19: HK0001185674 | D19: долговые ЦБ | E19: Банк Развития Казахстана | F19: 100.725 | G19: 101.1747 | H19: 3,08 | I19: 1 047 (3) | J19: %
A20: 16 | B20: 16BTRKe1 | C20: XS3067899610 | D20: долговые ЦБ | E20: Национальный управляющий холдинг "Байтерек" | F20: 101.598 | G20: 104.0505 | H20: 4,78 | I20: 918 (3) | J20: %
A21: 17 | B21: 17CCBN | C21: KZ0007786572 | D21: акции | E21: Банк ЦентрКредит | F21: 4682.82 | G21: – | H21: – | I21: – | J21: KZT
A22: 18 | B22: 18CCBNp | C22: KZ000A0H0930 | D22: акции | E22: Банк ЦентрКредит | F22: 7338.3 | G22: – | H22: – | I22: – | J22: KZT
A23: 19 | B23: 19CSECfe | C23: KZPF00000025 | D23: ЦБ инвест. фондов | E23: Сентрас Секьюритиз | F23: 6064840 | G23: – | H23: – | I23: – | J23: KZT
A24: 20 | B24: 20CSECtf | C24: KZPF00000280 | D24: ЦБ инвест. фондов | E24: Сентрас Секьюритиз | F24: 1790903.9 | G24: – | H24: – | I24: – | J24: KZT
A25: 21 | B25: 21EABRb40 | C25: KZ2D00009628 | D25: ЦБ МФО | E25: Евразийский банк развития | F25: 99.944 | G25: 100.4207 | H25: 5,84 | I25: 150 (0) | J25: %
A26: 22 | B26: 22EABRb42 | C26: KZ2D00009222 | D26: ЦБ МФО | E26: Евразийский банк развития | F26: 100 | G26: 102.4932 | H26: 16,22 | I26: 858 (2) | J26: %
A27: 23 | B27: 23EABRb53 | C27: KZ2D00013620 | D27: ЦБ МФО | E27: Евразийский банк развития | F27: 100 | G27: 101.1027 | H27: 17,48 | I27: 889 (2) | J27: %
A28: 24 | B28: 24FFIN_or | C28: KZPF00000082 | D28: ЦБ инвест. фондов | E28: Фридом Финанс | F28: 168.53 | G28: – | H28: – | I28: – | J28: USD
A29: 25 | B29: 25FFINgw | C29: KZPF00000090 | D29: ЦБ инвест. фондов | E29: Фридом Финанс | F29: 5523.73 | G29: – | H29: – | I29: – | J29: KZT
A30: 26 | B30: 26FPSTb5 | C30: KZ2P00011778 | D30: долговые ЦБ | E30: BASS Gold | F30: 100.1871 | G30: 101.5927 | H30: 10,74 | I30: 314 (1) | J30: %
A31: 27 | B31: 27HCBNb13 | C31: KZ2C00011195 | D31: долговые ЦБ | E31: Home Credit Bank | F31: 99.742 | G31: 102.4141 | H31: 18,25 | I31: 847 (2) | J31: %
A32: 28 | B32: 28HFINhl | C32: KZPF00000538 | D32: ЦБ инвест. фондов | E32: Halyk Finance | F32: 53502.61 | G32: – | H32: – | I32: – | J32: KZT
A33: 29 | B33: 29HFINhp | C33: KZPF00000546 | D33: ЦБ инвест. фондов | E33: Halyk Finance | F33: 74940.82 | G33: – | H33: – | I33: – | J33: KZT
A34: 30 | B34: 30HFINhs | C34: KZPF00000520 | D34: ЦБ инвест. фондов | E34: Halyk Finance | F34: 74075.51 | G34: – | H34: – | I34: – | J34: KZT
A35: 31 | B35: 31HFINhv | C35: KZPF00000041 | D35: ЦБ инвест. фондов | E35: Halyk Finance | F35: 590328.62 | G35: – | H35: – | I35: – | J35: KZT
A36: 32 | B36: 32HSBK | C36: KZ000A0LE0S4 | D36: акции | E36: Народный Банк Казахстана | F36: 355.23 | G36: – | H36: – | I36: – | J36: KZT
A37: 33 | B37: 33HSBKb22 | C37: KZ2C00012482 | D37: долговые ЦБ | E37: Народный Банк Казахстана | F37: 98.6496 | G37: 105.2492 | H37: 18,09 | I37: 774 (2) | J37: %
A38: 34 | B38: 34HSBKd | C38: US46627J3023 | D38: производные ЦБ | E38: Народный Банк Казахстана | F38: 26.88 | G38: – | H38: – | I38: – | J38: USD
A39: 35 | B39: 35IFDR | C39: KZ1C00000256 | D39: акции | E39: Teniz Capital Investment Banking | F39: 9490.25 | G39: – | H39: – | I39: – | J39: KZT
A40: 36 | B40: 36KAFIb16 | C40: KZ2C00015535 | D40: долговые ЦБ | E40: КазАгроФинанс | F40: 100.0482 | G40: 100.7343 | H40: 18,98 | I40: 1 787 (5) | J40: %
A41: 37 | B41: 37KAFIb17 | C41: KZ2C00015543 | D41: долговые ЦБ | E41: КазАгроФинанс | F41: 100.0482 | G41: 100.7343 | H41: 18,98 | I41: 1 787 (5) | J41: %
A42: 38 | B42: 38KASAb1 | C42: KZ2C00013753 | D42: долговые ЦБ | E42: Казахстанский электролизный завод | F42: 101.0925 | G42: 103.6203 | H42: 6,04 | I42: 940 (3) | J42: %
...

Sheet Риск цены за 20.10.25
A1: Дата оценки | B1: 45950
A3: № п/п | B3: Торговый код | C3: ISIN | D3: Алгоритмы и параметры расчета ЦБ | E3: Краткое наименование эмитента | F3: Расчетная цена | G3: Расчетная грязная | H3: Доходность до погашения. % годовых | I3: Дней до погашения | J3: Единица измерения цены
A4: 1 | B4: AAFD | C4: KZ1C00008721 | D4: Акции | E4: АО "АзияАгроФуд" | F4: 100 | G4: 100 | H4: 0 | I4: 0 | J4: KZT
A5: 2 | B5: AAL_KZ | C5: US02376R1023 | D5: Акции | E5: American Airlines | F5: 6423.5432 | G5: 6423.5432 | H5: 0 | I5: 0 | J5: KZT
A6: 3 | B6: AAPL_KZ | C6: US0378331005 | D6: Акции | E6: Apple Inc. | F6: 134367.4 | G6: 134367.4 | H6: 0 | I6: 0 | J6: KZT
A7: 4 | B7: ABK022_210 | C7: KZMJ00002103 | D7: Облигации | E7: Акимат Актюбинской области | F7: 100 | G7: 101.8417 | H7: 4.24 | I7: 324 | J7: %
A8: 5 | B8: ABK024_183 | C8: KZMJ00001832 | D8: Облигации | E8: Акимат Актюбинской области | F8: 100 | G8: 100.1381 | H8: 0.35 | I8: 218 | J8: %
A9: 6 | B9: ABK114_193 | C9: KZMJ00001931 | D9: Облигации | E9: Акимат Актюбинской области | F9: 100 | G9: 100.0013 | H9: 0.02 | I9: 3040 | J9: %
A10: 7 | B10: ABK119_006 | C10: KZMF00000069 | D10: Облигации | E10: Акимат Актюбинской области | F10: 100 | G10: 101.9486 | H10: 6.08 | I10: 1655 | J10: %
A11: 8 | B11: ABK119_081 | C11: KZMF00000812 | D11: Облигации | E11: Акимат Актюбинской области | F11: 100 | G11: 106.9619 | H11: 7.08 | I11: 2137 | J11: %
A12: 9 | B12: ABK131_021 | C12: KZMF00000218 | D12: Облигации | E12: Акимат Актюбинской области | F12: 100 | G12: 101.1183 | H12: 6.08 | I12: 2064 | J12: %
A13: 10 | B13: ABK143_032 | C13: KZMF00000325 | D13: Облигации | E13: Акимат Актюбинской области | F13: 100 | G13: 106.0661 | H13: 6.09 | I13: 2492 | J13: %
A14: 11 | B14: ABK143_033 | C14: KZMF00000333 | D14: Облигации | E14: Акимат Актюбинской области | F14: 100 | G14: 106.0661 | H14: 6.09 | I14: 2492 | J14: %
A15: 12 | B15: ABT_KZ | C15: US0028241000 | D15: Акции | E15: Abbott Lab. | F15: 68604.732 | G15: 68604.732 | H15: 0 | I15: 0 | J15: KZT
... A1064: 1061 | B1064: ZKK180_259 | C1064: KZMJ00002590 | D1064: Облигации | E1064: Акимат Западно-Казахстанской области | F1064: 92.1186 | G1064: 94.5861 | H1064: 20.59 | I1064: 5353 | J1064: %
