Workbook

Sheet ДУ
A1: Сентрас Секьюритиз | B1: 45895
A2: 1) Активы
A4: ЦБ
A5: Наименование эмитента и вид ЦБ | B5: ISIN | C5: Количество ЦБ | D5: Номинальная стоимость. тенге | E5: Ставка | F5: Дата зачисления/приобретения | G5: Дата погашения | H5: Чистая покупная стоимоcть | I5: Расчетная цена на 26.08.25 | J5: Расчетная грязная цена 26.08.25 | K5: Накопленный купон | L5: Суммарно-текущая рыночная стоимость | M5: Вес
A6: Министерство Финансов Республики Казахстан купонные МЕУКАМ | B6: KZKD00000535 | C6: =3250000-500000-500000-500000 -> 1750000 | D6: =3250000000-500000000-500000000-500000000 -> 1750000000 | E6: 5.49 | F6: 45491 | G6: 27.03.2027 | H6: =2755458875/3250000000*D6 -> 1483708625 | I6: =VLOOKUP(B6,'KASE за 26.08.25'!$C$5:$F$162,4,0) -> 85.4047 | J6: =VLOOKUP(B6,'KASE за 26.08.25'!$C$5:$G$162,5,0) -> 87.677 | K6: 39764375 | L6: =D6*I6/100+K6 -> 1534346625 | M6: =L6/$L$61 -> 0.05914255 | N6: =D6*E6%/360 -> 266875 | O6: =K6+N6 -> 40031250
A7: Министерство Финансов Республики Казахстан купонные МЕУКАМ | B7: KZKD00001137 | C7: 1950000 | D7: 1950000000 | E7: 10.4 | F7: 45491 | G7: 12.04.2028 | H7: 1838876000 | I7: =VLOOKUP(B7,'KASE за 26.08.25'!$C$5:$F$162,4,0) -> 87.2039 | J7: =VLOOKUP(B7,'KASE за 26.08.25'!$C$5:$G$162,5,0) -> 91.075 | K7: 75486667 | L7: =D7*I7/100+K7 -> 1.7759627e+09 | M7: =L7/$L$61 -> 0.068455825 | N7: =D7*E7%/360 -> 563333.33 | O7: =K7+N7 -> 76050000
A8: Министерство Финансов Республики Казахстан МЕУКАМ | B8: KZKD00001087 | C8: =1950000-202300-182000-187350 -> 1378350 | D8: =C8*1000 -> 1378350000 | E8: 11 | F8: 45491 | G8: 31.03.2029 | H8: =1855844250/1950000000*D8 -> 1.3117964e+09 | I8: =VLOOKUP(B8,'KASE за 26.08.25'!$C$5:$F$162,4,0) -> 85.1786 | J8: =VLOOKUP(B8,'KASE за 26.08.25'!$C$5:$G$162,5,0) -> 89.6397 | K8: 61489725 | L8: =D8*I8/100+K8 -> 1.235549e+09 | M8: =L8/$L$61 -> 0.047625168 | N8: =D8*E8%/360 -> 421162.5 | O8: =K8+N8 -> 61910888
A9: Министерство Финансов Республики Казахстан купонные МЕУКАМ | B9: KZKD00001160 | C9: =1950000-225000-225000-208000-225000-225000 -> 842000 | D9: =C9*1000 -> 842000000 | E9: 10.55 | F9: 45491 | G9: 28.07.2029 | H9: =1504310166.66923/1500000000*D9 -> 8.4441944e+08 | I9: =VLOOKUP(B9,'KASE за 26.08.25'!$C$5:$F$162,4,0) -> 83.1388 | J9: =VLOOKUP(B9,'KASE за 26.08.25'!$C$5:$G$162,5,0) -> 83.9594 | K9: 6909077.8 | L9: =D9*I9/100+K9 -> 7.0693777e+08 | M9: =L9/$L$61 -> 0.027249451 | N9: =D9*E9%/360 -> 246752.78 | O9: =K9+N9 -> 7155830.6
A10: Министерство Финансов Республики Казахстан купонные МЕУКАМ | B10: KZKD00001129 | C10: 1450000 | D10: 1450000000 | E10: 10.3 | F10: 45491 | G10: 17.03.2031 | H10: 1.307499e+09 | I10: =VLOOKUP(B10,'KASE за 26.08.25'!$C$5:$F$162,4,0) -> 77.6065 | J10: =VLOOKUP(B10,'KASE за 26.08.25'!$C$5:$G$162,5,0) -> 82.1557 | K10: 65962917 | L10: =D10*I10/100+K10 -> 1.1912572e+09 | M10: =L10/$L$61 -> 0.045917908 | N10: =D10*E10%/360 -> 414861.11 | O10: =K10+N10 -> 66377778
A11: Министерство Финансов Республики Казахстан МЕУКАМ | B11: KZKD00000949 | C11: 1950000 | D11: 1950000000 | E11: 8.45 | F11: 45491 | G11: 16.04.2032 | H11: 1.5403351e+09 | I11: =VLOOKUP(B11,'KASE за 26.08.25'!$C$5:$F$162,4,0) -> 67.9924 | J11: =VLOOKUP(B11,'KASE за 26.08.25'!$C$5:$G$162,5,0) -> 71.0438 | K11: 59502083 | L11: =D11*I11/100+K11 -> 1.3853539e+09 | M11: =L11/$L$61 -> 0.053399512 | N11: =D11*E11%/360 -> 457708.33 | O11: =K11+N11 -> 59959792
A12: Министерство Финансов Республики Казахстан Купонные Облигации | B12: KZKD00001152 | C12: =1950000-250000-250000-250000-218000 -> 982000 | D12: =C12*1000 -> 982000000 | E12: 10.65 | F12: 45491 | G12: 26.07.2032 | H12: =1897171250/1950000000*D12 -> 9.5539598e+08 | I12: =VLOOKUP(B12,'KASE за 26.08.25'!$C$5:$F$162,4,0) -> 75.9797 | J12: =VLOOKUP(B12,'KASE за 26.08.25'!$C$5:$G$162,5,0) -> 76.8672 | K12: 8715250 | L12: =D12*I12/100+K12 -> 754835904 | M12: =L12/$L$61 -> 0.02909572 | N12: =D12*E12%/360 -> 290508.33 | O12: =K12+N12 -> 9005758.3
A13: Министерство Финансов Республики Казахстан Купонные Облигации | B13: KZKD00001152 | C13: 250000 | D13: =C13*1000 -> 250000000 | E13: 10.65 | F13: 45673 | G13: 26.07.2032 | H13: =227969916.67/250000000*D13 -> 2.2796992e+08 | I13: =VLOOKUP(B13,'KASE за 26.08.25'!$C$5:$F$162,4,0) -> 75.9797 | J13: =VLOOKUP(B13,'KASE за 26.08.25'!$C$5:$G$162,5,0) -> 76.8672 | K13: 2218750 | L13: =D13*I13/100+K13 -> 192168000 | M13: =L13/$L$61 -> 0.0074072608 | N13: =D13*E13%/360 -> 73958.333 | O13: =K13+N13 -> 2292708.3
A14: Министерство Финансов Республики Казахстан купонные МЕУКАМ | B14: KZKD00000741 | C14: 1950000 | D14: 1950000000 | E14: 8.07 | F14: 45491 | G14: 12.05.2034 | H14: 1425576750 | I14: =VLOOKUP(B14,'KASE за 26.08.25'!$C$5:$F$173,4,0) -> 61.4628 | J14: =VLOOKUP(B14,'KASE за 26.08.25'!$C$5:$G$173,5,0) -> 63.7941 | K14: 45461000 | L14: =D14*I14/100+K14 -> 1243985600 | M14: =L14/$L$61 -> 0.047950365 | N14: =D14*E14%/360 -> 437125 | O14: =K14+N14 -> 45898125
A15: Министерство Финансов Республики Казахстан купонные МЕУКАМ | B15: KZKD00000832 | C15: 1950000 | D15: 1950000000 | E15: 8.07 | F15: 45491 | G15: 29.01.2035 | H15: 1449433375 | I15: =VLOOKUP(B15,'KASE за 26.08.25'!$C$5:$F$173,4,0) -> 59.9923 | J15: =VLOOKUP(B15,'KASE за 26.08.25'!$C$5:$G$173,5,0) -> 64.6326 | K15: 90484875 | L15: =D15*I15/100+K15 -> 1260334725 | M15: =L15/$L$61 -> 0.048580554 | N15: =D15*E15%/360 -> 437125 | O15: =K15+N15 -> 90922000
A16: Министерство Финансов Республики Казахстан купонные МЕУКАМ | B16: KZKD00000550 | C16: =312000-1 -> 311999 | D16: =C16*1000 -> 311999000 | E16: 5.5 | F16: 45509 | G16: 48328 | H16: 2.0448962e+08 | I16: =VLOOKUP(B16,'KASE за 26.08.25'!$C$5:$F$174,4,0) -> 56.6484 | J16: =VLOOKUP(B16,'KASE за 26.08.25'!$C$5:$G$174,5,0) -> 58.5123 | K16: 5815314.7 | L16: =D16*I16/100+K16 -> 1.8255776e+08 | M16: =L16/$L$61 -> 0.0070368267 | N16: =D16*E16%/360 -> 47666.514 | O16: =K16+N16 -> 5862981.2
A17: Министерство Финансов Республики Казахстан купонные МЕУКАМ | B17: KZKD00000550 | C17: 500000 | D17: 500000000 | E17: 5.5 | F17: 45532 | G17: 48328 | H17: 3.2653072e+08 | I17: =VLOOKUP(B17,'KASE за 26.08.25'!$C$5:$F$174,4,0) -> 56.6484 | J17: =VLOOKUP(B17,'KASE за 26.08.25'!$C$5:$G$174,5,0) -> 58.5123 | K17: 9319444.4 | L17: =D17*I17/100+K17 -> 2.9256144e+08 | M17: =L17/$L$61 -> 0.011277002 | N17: =D17*E17%/360 -> 76388.889 | O17: =K17+N17 -> 9395833.3
A18: Министерство Финансов Республики Казахстан купонные МЕУКАМ | B18: KZKD00000550 | C18: 500000 | D18: 500000000 | E18: 5.5 | F18: 45566 | G18: 48328 | H18: 3.3409056e+08 | I18: =VLOOKUP(B18,'KASE за 26.08.25'!$C$5:$F$174,4,0) -> 56.6484 | J18: =VLOOKUP(B18,'KASE за 26.08.25'!$C$5:$G$174,5,0) -> 58.5123 | K18: 9319444.4 | L18: =D18*I18/100+K18 -> 2.9256144e+08 | M18: =L18/$L$61 -> 0.011277002 | N18: =D18*E18%/360 -> 76388.889 | O18: =K18+N18 -> 9395833.3
A19: Министерство Финансов Республики Казахстан купонные МЕУКАМ | B19: KZKD00000550 | C19: 300000 | D19: =C19*1000 -> 300000000 | E19: 5.5 | F19: 45649 | G19: 48328 | H19: 2.0566557e+08 | I19: =VLOOKUP(B19,'KASE за 26.08.25'!$C$5:$F$174,4,0) -> 56.6484 | J19: =VLOOKUP(B19,'KASE за 26.08.25'!$C$5:$G$174,5,0) -> 58.5123 | K19: 5591666.7 | L19: =D19*I19/100+K19 -> 1.7553687e+08 | M19: =L19/$L$61 -> 0.0067662012 | N19: =D19*E19%/360 -> 45833.333 | O19: =K19+N19 -> 5637500
A20: Министерство Финансов Республики Казахстан купонные МЕУКАМ | B20: KZKD00000550 | C20: 300000 | D20: =C20*1000 -> 300000000 | E20: 5.5 | F20: 45677 | G20: 48328 | H20: 2.0236587e+08 | I20: =VLOOKUP(B20,'KASE за 26.08.25'!$C$5:$F$174,4,0) -> 56.6484 | J20: =VLOOKUP(B20,'KASE за 26.08.25'!$C$5:$G$174,5,0) -> 58.5123 | K20: 5591666.7 | L20: =D20*I20/100+K20 -> 1.7553687e+08 | M20: =L20/$L$61 -> 0.0067662012 | N20: =D20*E20%/360 -> 45833.333 | O20: =K20+N20 -> 5637500
A21: Министерство Финансов Республики Казахстан купонные МЕУКАМ | B21: KZKD00001160 | C21: 500000 | D21: =C21*1000 -> 500000000 | E21: 10.55 | F21: 45512 | G21: 28.07.2029 | H21: 4.5194078e+08 | I21: =VLOOKUP(B21,'KASE за 26.08.25'!$C$5:$F$162,4,0) -> 83.1388 | J21: =VLOOKUP(B21,'KASE за 26.08.25'!$C$5:$G$162,5,0) -> 83.9594 | K21: 4102777.8 | L21: =D21*I21/100+K21 -> 4.1979678e+08 | M21: =L21/$L$61 -> 0.016181384 | N21: =D21*E21%/360 -> 146527.78 | O21: =K21+N21 -> 4249305.6
A22: Министерство Финансов Республики Казахстан купонные МЕУКАМ | B22: KZKD00001160 | C22: 553430 | D22: =C22*1000 -> 553430000 | E22: 10.55 | F22: 45512 | G22: 28.07.2029 | H22: 4.9999941e+08 | I22: =VLOOKUP(B22,'KASE за 26.08.25'!$C$5:$F$162,4,0) -> 83.1388 | J22: =VLOOKUP(B22,'KASE за 26.08.25'!$C$5:$G$162,5,0) -> 83.9594 | K22: 4541200.6 | L22: =D22*I22/100+K22 -> 4.6465626e+08 | M22: =L22/$L$61 -> 0.017910527 | N22: =D22*E22%/360 -> 162185.74 | O22: =K22+N22 -> 4703386.3
A23: Министерство Финансов Республики Казахстан МЕУКАМ | B23: KZKD00000543 | C23: 636055 | D23: =C23*1000 -> 636055000 | E23: 5 | F23: 45519 | G23: 46861 | H23: 4.9999966e+08 | I23: =VLOOKUP(B23,'KASE за 26.08.25'!$C$5:$F$174,4,0) -> 76.3909 | J23: =VLOOKUP(B23,'KASE за 26.08.25'!$C$5:$G$174,5,0) -> 78.1687 | K23: 11307644 | L23: =D23*I23/100+K23 -> 4.9719578e+08 | M23: =L23/$L$61 -> 0.019164787 | N23: =D23*E23%/360 -> 88340.972 | O23: =K23+N23 -> 11395985
A24: Министерство Финансов Республики Казахстан купонные МЕУКАМ | B24: KZKD00000774 | C24: =715927-16841 -> 699086 | D24: =C24*1000 -> 699086000 | E24: 8.35 | F24: 45526 | G24: 50976 | H24: 4.8823782e+08 | I24: =VLOOKUP(B24,'KASE за 26.08.25'!$C$5:$F$173,4,0) -> 55.5548 | J24: =VLOOKUP(B24,'KASE за 26.08.25'!$C$5:$G$173,5,0) -> 56.2738 | K24: 5026622.5 | L24: =D24*I24/100+K24 -> 3.9340245e+08 | M24: =L24/$L$61 -> 0.015163995 | N24: =D24*E24%/360 -> 162149.11 | O24: =K24+N24 -> 5188771.6
A25: Министерство Финансов Республики Казахстан купонные МЕУКАМ | B25: KZKD00000774 | C25: 284073 | D25: =C25*1000 -> 284073000 | E25: 8.35 | F25: 45617 | G25: 50976 | H25: 2.0393645e+08 | I25: =VLOOKUP(B25,'KASE за 26.08.25'!$C$5:$F$173,4,0) -> 55.5548 | J25: =VLOOKUP(B25,'KASE за 26.08.25'!$C$5:$G$173,5,0) -> 56.2738 | K25: 2042563.8 | L25: =D25*I25/100+K25 -> 1.5985875e+08 | M25: =L25/$L$61 -> 0.0061618763 | N25: =D25*E25%/360 -> 65889.154 | O25: =K25+N25 -> 2108452.9
A26: Министерство Финансов Республики Казахстан МЕУКАМ | B26: KZKD00000840 | C26: 500000 | D26: =C26*1000 -> 500000000 | E26: 7.68 | F26: 45526 | G26: 47518 | H26: 417099000 | I26: =VLOOKUP(B26,'KASE за 26.08.25'!$C$5:$F$162,4,0) -> 72.8894 | J26: =VLOOKUP(B26,'KASE за 26.08.25'!$C$5:$G$162,5,0) -> 77.1987 | K26: 21546667 | L26: =D26*I26/100+K26 -> 3.8599367e+08 | M26: =L26/$L$61 -> 0.014878418 | N26: =D26*E26%/360 -> 106666.67 | O26: =K26+N26 -> 21653333
A27: Министерство Финансов Республики Казахстан МЕУКАМ | B27: KZKD00000840 | C27: 500000 | D27: =C27*1000 -> 500000000 | E27: 7.68 | F27: 45527 | G27: 47518 | H27: 4.1494417e+08 | I27: =VLOOKUP(B27,'KASE за 26.08.25'!$C$5:$F$162,4,0) -> 72.8894 | J27: =VLOOKUP(B27,'KASE за 26.08.25'!$C$5:$G$162,5,0) -> 77.1987 | K27: 21546667 | L27: =D27*I27/100+K27 -> 3.8599367e+08 | M27: =L27/$L$61 -> 0.014878418 | N27: =D27*E27%/360 -> 106666.67 | O27: =K27+N27 -> 21653333
A28: Министерство Финансов Республики Казахстан МЕУКАМ | B28: KZKD00000840 | C28: 500000 | D28: =C28*1000 -> 500000000 | E28: 7.68 | F28: 45561 | G28: 47518 | H28: 4.2179517e+08 | I28: =VLOOKUP(B28,'KASE за 26.08.25'!$C$5:$F$162,4,0) -> 72.8894 | J28: =VLOOKUP(B28,'KASE за 26.08.25'!$C$5:$G$162,5,0) -> 77.1987 | K28: 21546667 | L28: =D28*I28/100+K28 -> 3.8599367e+08 | M28: =L28/$L$61 -> 0.014878418 | N28: =D28*E28%/360 -> 106666.67 | O28: =K28+N28 -> 21653333
A29: Евразийский банк развития | B29: KZ2D00011863 | C29: 1700000 | D29: =C29*1000 -> 1700000000 | E29: 14.3 | F29: 45538 | G29: 46633 | H29: 1700000000 | I29: =VLOOKUP(B29,'Риск цены за 26.08.25'!$C$4:$G$963,4,0) -> 93.83253 | J29: =VLOOKUP(B29,'Риск цены за 26.08.25'!$C$4:$G$963,5,0) -> 107.85443 | K29: 2.3837306e+08 | L29: =D29*I29/100+K29 -> 1.8335261e+09 | M29: =L29/$L$61 -> 0.070674647 | N29: =D29*E29%/360 -> 675277.78 | O29: =K29+N29 -> 2.3904833e+08
A30: Министерство Финансов Республики Казахстан МЕУКАМ | B30: KZKD00001244 | C30: 500000 | D30: =C30*1000 -> 500000000 | E30: 12 | F30: 45540 | G30: 47901 | H30: 5.0216167e+08 | I30: =VLOOKUP(B30,'KASE за 26.08.25'!$C$5:$F$162,4,0) -> 83.4806 | J30: =VLOOKUP(B30,'KASE за 26.08.25'!$C$5:$G$162,5,0) -> 89.6139 | K30: 30666667 | L30: =D30*I30/100+K30 -> 4.4806967e+08 | M30: =L30/$L$61 -> 0.017271184 | N30: =D30*E30%/360 -> 166666.67 | O30: =K30+N30 -> 30833333
A31: Министерство Финансов Республики Казахстан МЕУКАМ | B31: KZKD00001251 | C31: 300000 | D31: =C31*1000 -> 300000000 | E31: 12 | F31: 45547 | G31: 47549 | H31: 302854400 | I31: =VLOOKUP(B31,'KASE за 26.08.25'!$C$5:$F$162,4,0) -> 85.5179 | J31: =VLOOKUP(B31,'KASE за 26.08.25'!$C$5:$G$162,5,0) -> 91.1512 | K31: 16900000 | L31: =D31*I31/100+K31 -> 273453700 | M31: =L31/$L$61 -> 0.010540479 | N31: =D31*E31%/360 -> 100000 | O31: =K31+N31 -> 17000000
A32: Министерство Финансов Республики Казахстан МЕУКАМ | B32: KZKD00001251 | C32: 288579 | D32: =C32*1000 -> 288579000 | E32: 12 | F32: 45582 | G32: 47549 | H32: 2.9999932e+08 | I32: =VLOOKUP(B32,'KASE за 26.08.25'!$C$5:$F$162,4,0) -> 85.5179 | J32: =VLOOKUP(B32,'KASE за 26.08.25'!$C$5:$G$162,5,0) -> 91.1512 | K32: 16256617 | L32: =D32*I32/100+K32 -> 2.6304332e+08 | M32: =L32/$L$61 -> 0.010139203 | N32: =D32*E32%/360 -> 96193 | O32: =K32+N32 -> 16352810
A33: АО "Национальный управляющий холдинг "Байтерек" | B33: KZ2C00012698 | C33: 300000 | D33: =C33*1000 -> 300000000 | E33: 13.89 | F33: 45624 | G33: 46109 | H33: 300000000 | I33: =VLOOKUP(B33,'Риск цены за 26.08.25'!$C$4:$G$963,4,0) -> 98.378655 | J33: =VLOOKUP(B33,'Риск цены за 26.08.25'!$C$4:$G$963,5,0) -> 101.77395 | K33: 10186000 | L33: =D33*I33/100+K33 -> 3.0532196e+08 | M33: =L33/$L$61 -> 0.011768866 | N33: =D33*E33%/360 -> 115750 | O33: =K33+N33 -> 10301750
A34: Министерство Финансов Республики Казахстан МЕУКАМ | B34: KZKD00000964 | C34: =220000-213000 -> 7000 | D34: =C34*1000 -> 7000000 | E34: 8.44 | F34: 45639 | G34: 47978 | H34: =182967986.67/220000000*D34 -> 5821708.7 | I34: =VLOOKUP(B34,'KASE за 26.08.25'!$C$5:$F$162,4,0) -> 70.7668 | J34: =VLOOKUP(B34,'KASE за 26.08.25'!$C$5:$G$162,5,0) -> 73.2519 | K34: 173957.78 | L34: =D34*I34/100+K34 -> 5127633.8 | M34: =L34/$L$61 -> 0.00019764852 | N34: =D34*E34%/360 -> 1641.1111 | O34: =K34+N34 -> 175598.89
A35: Министерство Финансов Республики Казахстан МЕУКАМ | B35: KZKD00001236 | C35: =173000-163000 -> 10000 | D35: =C35*1000 -> 10000000 | E35: 14 | F35: 45639 | G35: 48353 | H35: =188266096.67/173000000*D35 -> 10882433 | I35: =VLOOKUP(B35,'KASE за 26.08.25'!$C$5:$F$162,4,0) -> 89.1595 | J35: =VLOOKUP(B35,'KASE за 26.08.25'!$C$5:$G$162,5,0) -> 92.9317 | K35: 377222.22 | L35: =D35*I35/100+K35 -> 9293172.2 | M35: =L35/$L$61 -> 0.00035821235 | N35: =D35*E35%/360 -> 3888.8889 | O35: =K35+N35 -> 381111.11
A36: Министерство Финансов Республики Казахстан МЕУКАМ | B36: KZKD00001079 | C36: 300000 | D36: =C36*1000 -> 300000000 | E36: 8.7 | F36: 45651 | G36: 50082 | H36: 237511300 | I36: =VLOOKUP(B36,'KASE за 26.08.25'!$C$5:$F$174,4,0) -> 59.812 | J36: =VLOOKUP(B36,'KASE за 26.08.25'!$C$5:$G$174,5,0) -> 64.5245 | K36: 14137500 | L36: =D36*I36/100+K36 -> 193573500 | M36: =L36/$L$61 -> 0.0074614368 | N36: =D36*E36%/360 -> 72500 | O36: =K36+N36 -> 14210000
A37: Министерство Финансов Республики Казахстан МЕУКАМ | B37: KZKD00001079 | C37: 200000 | D37: =C37*1000 -> 200000000 | E37: 8.7 | F37: 45680 | G37: 50082 | H37: 157353400 | I37: =VLOOKUP(B37,'KASE за 26.08.25'!$C$5:$F$174,4,0) -> 59.812 | J37: =VLOOKUP(B37,'KASE за 26.08.25'!$C$5:$G$174,5,0) -> 64.5245 | K37: 9425000 | L37: =D37*I37/100+K37 -> 1.29049e+08 | M37: =L37/$L$61 -> 0.0049742912 | N37: =D37*E37%/360 -> 48333.333 | O37: =K37+N37 -> 9473333.3
A38: Министерство Финансов Республики Казахстан МЕУКАМ | B38: KZKD00001202 | C38: 263000 | D38: =C38*1000 -> 263000000 | E38: 11 | F38: 45656 | G38: 47518 | H38: 2.6372196e+08 | I38: =VLOOKUP(B38,'KASE за 26.08.25'!$C$5:$F$162,4,0) -> 82.6812 | J38: =VLOOKUP(B38,'KASE за 26.08.25'!$C$5:$G$162,5,0) -> 88.8534 | K38: 16232944 | L38: =D38*I38/100+K38 -> 2.336845e+08 | M38: =L38/$L$61 -> 0.0090075456 | N38: =D38*E38%/360 -> 80361.111 | O38: =K38+N38 -> 16313306
A39: Министерство Финансов Республики Казахстан МЕУКАМ | B39: KZKD00001210 | C39: 341000 | D39: =C39*1000 -> 341000000 | E39: 15.3 | F39: 45657 | G39: 47180 | H39: 396883762 | I39: =VLOOKUP(B39,'KASE за 26.08.25'!$C$5:$F$162,4,0) -> 96.1466 | J39: =VLOOKUP(B39,'KASE за 26.08.25'!$C$5:$G$162,5,0) -> 103.4991 | K39: 25072025 | L39: =D39*I39/100+K39 -> 3.5293193e+08 | M39: =L39/$L$61 -> 0.013604028 | N39: =D39*E39%/360 -> 144925 | O39: =K39+N39 -> 25216950
A40: Министерство Финансов Республики Казахстан МЕУКАМ | B40: KZKD00001095 | C40: =214727-132000 -> 82727 | D40: =C40*1000 -> 82727000 | E40: 10.47 | F40: 45673 | G40: 47053 | H40: 77053072 | I40: =VLOOKUP(B40,'KASE за 26.08.25'!$C$5:$F$162,4,0) -> 85.3853 | J40: =VLOOKUP(B40,'KASE за 26.08.25'!$C$5:$G$162,5,0) -> 94.0812 | K40: 7193871 | L40: =D40*I40/100+K40 -> 77830568 | M40: =L40/$L$61 -> 0.0030000381 | N40: =D40*E40%/360 -> 24059.769 | O40: =K40+N40 -> 7217930.8
A41: Министерство Финансов Республики Казахстан МЕУКАМ | B41: KZKD00000790 | C41: 227500 | D41: =C41*1000 -> 227500000 | E41: 7.68 | F41: 45702 | G41: 47343 | H41: 1.8902823e+08 | I41: =VLOOKUP(B41,'KASE за 26.08.25'!$C$5:$F$162,4,0) -> 75.1502 | J41: =VLOOKUP(B41,'KASE за 26.08.25'!$C$5:$G$162,5,0) -> 75.4275 | K41: 630933.33 | L41: =D41*I41/100+K41 -> 1.7159764e+08 | M41: =L41/$L$61 -> 0.0066143606 | N41: =D41*E41%/360 -> 48533.333 | O41: =K41+N41 -> 679466.67
...

Sheet KASE за 26.08.25
A1: Дата оценки | B1: 45895
A3: № п/п | B3: Код | C3: ISIN | D3: Вид ценной бумаги | E3: Компания | F3: Рыночная цена | G3: Рыночная "грязная" цена | H3: Доходность до погашения, % годовых | I3: Срок до погашения | J3: Единица измерения цены
A5: 1 | B5: 1AIRA | C5: KZ1C00004050 | D5: акции | E5: Эйр Астана | F5: 746.2 | G5: – | H5: – | I5: – | J5: KZT
A6: 2 | B6: 2AIRAd | C6: US0090632078 | D6: производные ЦБ | E6: Эйр Астана | F6: 5.69 | G6: – | H6: – | I6: – | J6: USD
A7: 3 | B7: 3AKZM | C7: KZ1C00001288 | D7: акции | E7: Актюбинский завод металлоконструкций | F7: 6266.18 | G7: – | H7: – | I7: – | J7: KZT
A8: 4 | B8: 4ALMSb1 | C8: KZ2C00012953 | D8: долговые ЦБ | E8: АК Алтыналмас | F8: 100.015 | G8: 101.3483 | H8: 7,99 | I8: 840 (2) | J8: %
A9: 5 | B9: 5BCCIbe | C9: KZPF00000553 | D9: ЦБ инвест. фондов | E9: BCC Invest | F9: 1465.25 | G9: – | H9: – | I9: – | J9: KZT
A10: 6 | B10: 6BCCIrb | C10: KZPF00000231 | D10: ЦБ инвест. фондов | E10: BCC Invest | F10: 6.97 | G10: – | H10: – | I10: – | J10: KZT
A11: 7 | B11: 7BIGDb5 | C11: KZ2D00012861 | D11: долговые ЦБ | E11: Частная компания BI Development Ltd. | F11: 99.8903 | G11: 104.6028 | H11: 19,50 | I11: 633 (2) | J11: %
A12: 8 | B12: 8BRKZe18 | C12: XS3032932645 | D12: долговые ЦБ | E12: Банк Развития Казахстана | F12: 102.63 | G12: 104.8019 | H12: 4,98 | I12: 1 661 (5) | J12: %
A13: 9 | B13: 9BRKZe4 | C13: XS0248160102 | D13: долговые ЦБ | E13: Банк Развития Казахстана | F13: 100.0093 | G13: 102.5593 | H13: 5,97 | I13: 207 (1) | J13: %
A14: 10 | B14: 10BTRKe1 | C14: XS3067899610 | D14: долговые ЦБ | E14: Национальный управляющий холдинг "Байтерек" | F14: 101.1559 | G14: 102.7909 | H14: 4,98 | I14: 972 (3) | J14: %
A15: 11 | B15: 11CCBN | C15: KZ0007786572 | D15: акции | E15: Банк ЦентрКредит | F15: 4458.18 | G15: – | H15: – | I15: – | J15: KZT
A16: 12 | B16: 12CCBNp | C16: KZ000A0H0930 | D16: акции | E16: Банк ЦентрКредит | F16: 6635.48 | G16: – | H16: – | I16: – | J16: KZT
A17: 13 | B17: 13CSECfe | C17: KZPF00000025 | D17: ЦБ инвест. фондов | E17: Сентрас Секьюритиз | F17: 5886779.2 | G17: – | H17: – | I17: – | J17: KZT
A18: 14 | B18: 14CSECtf | C18: KZPF00000280 | D18: ЦБ инвест. фондов | E18: Сентрас Секьюритиз | F18: 1746265.6 | G18: – | H18: – | I18: – | J18: KZT
A19: 15 | B19: 15EABRb40 | C19: KZ2D00009628 | D19: ЦБ МФО | E19: Евразийский банк развития | F19: 99.7596 | G19: 102.2383 | H19: 6,15 | I19: 204 (1) | J19: %
A20: 16 | B20: 16EABRb42 | C20: KZ2D00009222 | D20: ЦБ МФО | E20: Евразийский банк развития | F20: 100 | G20: 100.0445 | H20: 16,25 | I20: 913 (3) | J20: %
A21: 17 | B21: 17EABRb53 | C21: KZ2D00013620 | D21: ЦБ МФО | E21: Евразийский банк развития | F21: 100 | G21: 107.2877 | H21: 17,47 | I21: 944 (3) | J21: %
A22: 18 | B22: 18FFINgw | C22: KZPF00000090 | D22: ЦБ инвест. фондов | E22: Фридом Финанс | F22: 5485.73 | G22: – | H22: – | I22: – | J22: KZT
A23: 19 | B23: 19FHJIag | C23: KZPF00000132 | D23: ЦБ инвест. фондов | E23: Alatau City Invest | F23: 1034.92 | G23: – | H23: – | I23: – | J23: USD
A24: 20 | B24: 20FHJIpc | C24: KZPF00000140 | D24: ЦБ инвест. фондов | E24: Alatau City Invest | F24: 1162.49 | G24: – | H24: – | I24: – | J24: USD
A25: 21 | B25: 21HCBNb13 | C25: KZ2C00011195 | D25: долговые ЦБ | E25: Home Credit Bank | F25: 99.799 | G25: 108.8236 | H25: 18,25 | I25: 901 (3) | J25: %
A26: 22 | B26: 22HCBNb17 | C26: KZ2C00014066 | D26: долговые ЦБ | E26: Home Credit Bank | F26: 101.0196 | G26: 103.2479 | H26: 18,75 | I26: 1 758 (5) | J26: %
A27: 23 | B27: 23HFINhl | C27: KZPF00000538 | D27: ЦБ инвест. фондов | E27: Halyk Finance | F27: 53156.59 | G27: – | H27: – | I27: – | J27: KZT
A28: 24 | B28: 24HFINhp | C28: KZPF00000546 | D28: ЦБ инвест. фондов | E28: Halyk Finance | F28: 73837.99 | G28: – | H28: – | I28: – | J28: KZT
A29: 25 | B29: 25HFINhs | C29: KZPF00000520 | D29: ЦБ инвест. фондов | E29: Halyk Finance | F29: 72906.9 | G29: – | H29: – | I29: – | J29: KZT
A30: 26 | B30: 26HFINhv | C30: KZPF00000041 | D30: ЦБ инвест. фондов | E30: Halyk Finance | F30: 580686.49 | G30: – | H30: – | I30: – | J30: KZT
A31: 27 | B31: 27HSBK | C31: KZ000A0LE0S4 | D31: акции | E31: Народный Банк Казахстана | F31: 370.39 | G31: – | H31: – | I31: – | J31: KZT
A32: 28 | B32: 28HSBKd | C32: US46627J3023 | D32: производные ЦБ | E32: Народный Банк Казахстана | F32: 26.73 | G32: – | H32: – | I32: – | J32: USD
A33: 29 | B33: 29IFDR | C33: KZ1C00000256 | D33: акции | E33: Teniz Capital Investment Banking | F33: 9355.15 | G33: – | H33: – | I33: – | J33: KZT
A34: 30 | B34: 30KCEL | C34: KZ1C00000876 | D34: акции | E34: Kcell | F34: 3383.02 | G34: – | H34: – | I34: – | J34: KZT
A35: 31 | B35: 31KEGC | C35: KZ1C00000959 | D35: акции | E35: KEGOC | F35: 1440.15 | G35: – | H35: – | I35: – | J35: KZT
A36: 32 | B36: 32KFUSb44 | C36: KZ2C00008902 | D36: долговые ЦБ | E36: Казахстанский фонд устойчивости | F36: 100.1076 | G36: 104.3203 | H36: 17,29 | I36: 98 (0) | J36: %
A37: 33 | B37: 33KFUSb45 | C37: KZ2C00008910 | D37: долговые ЦБ | E37: Казахстанский фонд устойчивости | F37: 99.954 | G37: 107.1211 | H37: 17,33 | I37: 34 (0) | J37: %
A38: 34 | B38: 34KMGZ | C38: KZ1C00001122 | D38: акции | E38: Национальная компания "КазМунайГаз" | F38: 19776.9 | G38: – | H38: – | I38: – | J38: KZT
A39: 35 | B39: 35KMGZe12 | C39: XS1595714087 | D39: долговые ЦБ | E39: Национальная компания "КазМунайГаз" | F39: 90.4009 | G39: 92.4294 | H39: 6,59 | I39: 7 793 (22) | J39: %
A40: 36 | B40: 36KMGZe14 | C40: XS1807300105 | D40: долговые ЦБ | E40: Национальная компания "КазМунайГаз" | F40: 101.8121 | G40: 103.6336 | H40: 4,93 | I40: 1 678 (5) | J40: %
A41: 37 | B41: 37KMGZe15 | C41: XS1807299331 | D41: долговые ЦБ | E41: Национальная компания "КазМунайГаз" | F41: 96.0027 | G41: 98.1631 | H41: 6,72 | I41: 8 338 (23) | J41: %
A42: 38 | B42: 38KMGZe16 | C42: XS2242422397 | D42: долговые ЦБ | E42: Национальная компания "КазМунайГаз" | F42: 88.5416 | G42: 89.8249 | H42: 5,35 | I42: 2 748 (8) | J42: %
...

Sheet Риск цены за 26.08.25
A1: Дата оценки | C1: 45895
A3: № п/п | B3: Торговый код | C3: ISIN | D3: Алгоритмы и параметры расчета ЦБ | E3: Краткое наименование эмитента | F3: Расчетная цена | G3: Расчетная грязная | H3: Доходность до погашения. % годовых | I3: Дней до погашения | J3: Единица измерения цены
A4: 1 | B4: AAFD | C4: KZ1C00008721 | D4: Акции | E4: АО "АзияАгроФуд" | F4: 100 | G4: 100 | H4: 0 | I4: 0 | J4: KZT
A5: 2 | B5: AAL_KZ | C5: US02376R1023 | D5: Акции | E5: American Airlines | F5: 7046.0396 | G5: 7046.0396 | H5: 0 | I5: 0 | J5: KZT
A6: 3 | B6: AAPL_KZ | C6: US0378331005 | D6: Акции | E6: Apple Inc. | F6: 122517.6 | G6: 122517.6 | H6: 0 | I6: 0 | J6: KZT
A7: 4 | B7: ABK022_210 | C7: KZMJ00002103 | D7: Облигации | E7: Акимат Актюбинской области | F7: 100 | G7: 101.2042 | H7: 4.23 | I7: 378 | J7: %
A8: 5 | B8: ABK024_183 | C8: KZMJ00001832 | D8: Облигации | E8: Акимат Актюбинской области | F8: 100 | G8: 100.0856 | H8: 0.35 | I8: 272 | J8: %
A9: 6 | B9: ABK114_193 | C9: KZMJ00001931 | D9: Облигации | E9: Акимат Актюбинской области | F9: 100 | G9: 100.0183 | H9: 0.02 | I9: 3094 | J9: %
A10: 7 | B10: ABK119_006 | C10: KZMF00000069 | D10: Облигации | E10: Акимат Актюбинской области | F10: 100 | G10: 101.0336 | H10: 6.08 | I10: 1709 | J10: %
A11: 8 | B11: ABK119_081 | C11: KZMF00000812 | D11: Облигации | E11: Акимат Актюбинской области | F11: 100 | G11: 105.8969 | H11: 7.08 | I11: 2191 | J11: %
A12: 9 | B12: ABK131_021 | C12: KZMF00000218 | D12: Облигации | E12: Акимат Актюбинской области | F12: 100 | G12: 100.2033 | H12: 6.09 | I12: 2118 | J12: %
A13: 10 | B13: ABK143_032 | C13: KZMF00000325 | D13: Облигации | E13: Акимат Актюбинской области | F13: 100 | G13: 105.1511 | H13: 6.08 | I13: 2546 | J13: %
A14: 11 | B14: ABK143_033 | C14: KZMF00000333 | D14: Облигации | E14: Акимат Актюбинской области | F14: 100 | G14: 105.1511 | H14: 6.08 | I14: 2546 | J14: %
A15: 12 | B15: ABT_KZ | C15: US0028241000 | D15: Акции | E15: Abbott Lab. | F15: 70476.453 | G15: 70476.453 | H15: 0 | I15: 0 | J15: KZT
... A1012: 1009 | B1012: ZKK143_044 | C1012: KZMF00000440 | D1012: Облигации | E1012: Акимат Западно-Казахстанской области | F1012: 100 | G1012: 105.1511 | H1012: 6.08 | I1012: 2546 | J1012: %
